Workbook

Sheet 2026년 휴일 등
B1: 2026년도 휴일 | F1: 2026년도 중정비 일정
A2: 2026 | B2: 신정 | C2: 46023 | D2: 46023 | F2: 편성 | G2: 시작일 | H2: 종료일 | I2: 작업일
B3: 설연휴 | C3: 46069 | D3: 46069 | F3: 114 | G3: 46010 | H3: 46057 | I3: 32
B4: 설날 | C4: 46070 | D4: 46070 | F4: 115 | G4: 46062 | H4: 46111 | I4: 32
B5: 설연휴 | C5: 46071 | D5: 46071 | F5: 116 | G5: 46114 | H5: 46162 | I5: 32
B6: 3∙1 | C6: 46082 | D6: 46082 | F6: 117 | G6: 46169 | H6: 46213 | I6: 32
B7: 대체공휴일 | C7: 46083 | D7: 46083 | F7: 118 | G7: 46218 | H7: 46265 | I7: 32
B8: 근로자날 | C8: 46143 | D8: 46143 | F8: 119 | G8: 46268 | H8: 46318 | I8: 32
B9: 어린이날 | C9: 46147 | D9: 46147 | F9: 120 | G9: 46323 | H9: 46366 | I9: 32
B10: 5∙18 | C10: 46160 | D10: 46160 | F10: 121 | G10: 46371 | H10: 46416 | I10: 32
B11: 부처님오신날 | C11: 46166 | D11: 46166
B12: 부처님대체공휴일 | C12: 46167 | D12: 46167
B13: 춘계체육행사 | C13: 46171 | D13: 46171
A14: 추가 | B14: 지방선거 | C14: 46176 | D14: 46176
B15: 현충일 | C15: 46179 | D15: 46179
A16: 추가 | B16: 제헌절 | C16: 46220 | D16: =C16 -> 46220
B17: 광복절 | C17: 46249 | D17: 46249
B18: 대체공휴일 | C18: 46251 | D18: 46251
B19: 추석연휴 | C19: 46289 | D19: 46289
B20: 추석 | C20: 46290 | D20: 46290
B21: 추석연휴 | C21: 46291 | D21: 46291
B22: 개천절 | C22: 46298 | D22: 46298
B23: 대체공휴일 | C23: 46300 | D23: 46300
B24: 한글날 | C24: 46304 | D24: 46304
B25: 추계체육행사 | C25: 46311 | D25: 46311
B26: 성탄절 | C26: 46381 | D26: 46381

Sheet 2026.1.
A1: 전동차 정기검사 및 대청소 계획
A2: [2026.1.] [차량운영처 차량팀]
A3: 일자 | B3: 46023 | C3: 46024 | D3: 46025 | E3: 46026 | F3: 46027 | G3: 46028 | H3: 46029 | I3: 46030 | J3: 46031 | K3: 46032 | L3: 46033 | M3: 46034 | N3: 46035 | O3: 46036 | P3: 46037 | Q3: 46038 | R3: 46039 | S3: 46040 | T3: 46041 | U3: 46042 | V3: 46043 | W3: 46044 | X3: 46045 | Y3: 46046 | Z3: 46047 | AA3: 46048 | AB3: 46049 | AC3: 46050 | AD3: 46051 | AE3: 46052 | AF3: 46053 | AG3: 소계
A5: 편성 요일 | B5: 46023 | C5: 46024 | D5: 46025 | E5: 46026 | F5: 46027 | G5: 46028 | H5: 46029 | I5: 46030 | J5: 46031 | K5: 46032 | L5: 46033 | M5: 46034 | N5: 46035 | O5: 46036 | P5: 46037 | Q5: 46038 | R5: 46039 | S5: 46040 | T5: 46041 | U5: 46042 | V5: 46043 | W5: 46044 | X5: 46045 | Y5: 46046 | Z5: 46047 | AA5: 46048 | AB5: 46049 | AC5: 46050 | AD5: 46051 | AE5: 46052 | AF5: 46053 | AG5: 대 | AH5: 7D | AI5: 4M | AJ5: 시행 만료일 | AK5: 이달 시행일 | AL5: 다음 시행일
A6: 101 | E6: 7D | M6: 7D | S6: 7D | Z6: 7D | AA6: 청 | AG6: =COUNTIF(B6:AF6,"청") -> 1 | AH6: =COUNTIF(B6:AF6,"7D") -> 4 | AI6: 0 | AJ6: ='[1]2025.12.'!AL6 -> 46049 | AK6: =IFERROR(INDEX($B$3:$AF$5,1,MATCH("청",B6:AF6,0)),"") -> 46048 | AL6: =IFERROR(AK6+40,"") -> 46088
A7: 102 | C7: 7D | J7: 7D | Q7: 7D | X7: 7D | AD7: 청 | AE7: 7D | AG7: =COUNTIF(B7:AF7,"청") -> 1 | AH7: =COUNTIF(B7:AF7,"7D") -> 5 | AI7: 0 | AJ7: ='[1]2025.12.'!AL7 -> 46060 | AK7: =IFERROR(INDEX($B$3:$AF$5,1,MATCH("청",B7:AF7,0)),"") -> 46051 | AL7: =IFERROR(AK7+40,"") -> 46091
A8: 103 | B8: 7D | I8: 7D | P8: 7D | W8: 7D | AD8: 7D | AG8: =COUNTIF(B8:AF8,"청") -> 0 | AH8: =COUNTIF(B8:AF8,"7D") -> 5 | AI8: 0 | AJ8: ='[1]2025.12.'!AL8 -> 46054 | AK8: =IFERROR(INDEX($B$3:$AF$5,1,MATCH("청",B8:AF8,0)),"") | AL8: =AJ8 -> 46054
A9: 104 | D9: 7D | K9: 7D | R9: 7D | Y9: 7D | AE9: 청 | AF9: 7D | AG9: =COUNTIF(B9:AF9,"청") -> 1 | AH9: =COUNTIF(B9:AF9,"7D") -> 5 | AI9: 0 | AJ9: ='[1]2025.12.'!AL9 -> 46055 | AK9: =IFERROR(INDEX($B$3:$AF$5,1,MATCH("청",B9:AF9,0)),"") -> 46052 | AL9: =IFERROR(AK9+40,"") -> 46092
A10: 105 | B10: 105(1Y) | F10: 청 | J10: 7D | Q10: 7D | X10: 7D | AE10: 7D | AG10: =COUNTIF(B10:AF10,"청") -> 1 | AH10: =COUNTIF(B10:AF10,"7D") -> 4 | AI10: 0 | AJ10: ='[1]2025.12.'!AL10 -> 46040 | AK10: =IFERROR(INDEX($B$3:$AF$5,1,MATCH("청",B10:AF10,0)),"") -> 46027 | AL10: =IFERROR(AK10+40,"") -> 46067
A11: 106 | H11: 7D | N11: 7D | O11: 청 | U11: 7D | AB11: 7D | AG11: =COUNTIF(B11:AF11,"청") -> 1 | AH11: =COUNTIF(B11:AF11,"7D") -> 4 | AI11: 0 | AJ11: ='[1]2025.12.'!AL11 -> 46057 | AK11: =IFERROR(INDEX($B$3:$AF$5,1,MATCH("청",B11:AF11,0)),"") -> 46036 | AL11: =IFERROR(AK11+40,"") -> 46076
A12: 107 | C12: 청 | H12: 7D | O12: 7D | V12: 7D | AC12: 7D | AG12: =COUNTIF(B12:AF12,"청") -> 1 | AH12: =COUNTIF(B12:AF12,"7D") -> 4 | AI12: 0 | AJ12: ='[1]2025.12.'!AL12 -> 46028 | AK12: =IFERROR(INDEX($B$3:$AF$5,1,MATCH("청",B12:AF12,0)),"") -> 46024 | AL12: =IFERROR(AK12+40,"") -> 46064
A13: 108 | D13: 7D | K13: 7D | P13: 108(8M) | V13: 청 | AA13: 7D | AG13: =COUNTIF(B13:AF13,"청") -> 1 | AH13: =COUNTIF(B13:AF13,"7D") -> 3 | AI13: 0 | AJ13: ='[1]2025.12.'!AL13 -> 46062 | AK13: =IFERROR(INDEX($B$3:$AF$5,1,MATCH("청",B13:AF13,0)),"") -> 46043 | AL13: =IFERROR(AK13+40,"") -> 46083
A14: 109 | H14: 7D | I14: 청 | O14: 7D | V14: 7D | AC14: 7D | AG14: =COUNTIF(B14:AF14,"청") -> 1 | AH14: =COUNTIF(B14:AF14,"7D") -> 4 | AI14: 0 | AJ14: ='[1]2025.12.'!AL14 -> 46035 | AK14: =IFERROR(INDEX($B$3:$AF$5,1,MATCH("청",B14:AF14,0)),"") -> 46030 | AL14: =IFERROR(AK14+40,"") -> 46070
A15: 110 | F15: 7D | M15: 7D | Q15: 청 | T15: 7D | AA15: 7D | AG15: =COUNTIF(B15:AF15,"청") -> 1 | AH15: =COUNTIF(B15:AF15,"7D") -> 4 | AI15: 0 | AJ15: ='[1]2025.12.'!AL15 -> 46041 | AK15: =IFERROR(INDEX($B$3:$AF$5,1,MATCH("청",B15:AF15,0)),"") -> 46038 | AL15: =IFERROR(AK15+40,"") -> 46078
A16: 111 | F16: 7D | J16: 111(3Y-4M) | P16: 청 | V16: 7D | AC16: 7D | AG16: =COUNTIF(B16:AF16,"청") -> 1 | AH16: =COUNTIF(B16:AF16,"7D") -> 3 | AI16: 0 | AJ16: ='[1]2025.12.'!AL16 -> 46029 | AK16: =IFERROR(INDEX($B$3:$AF$5,1,MATCH("청",B16:AF16,0)),"") -> 46037 | AL16: =IFERROR(AK16+40,"") -> 46077
A17: 112 | B17: 7D | I17: 7D | M17: 청 | O17: 7D | W17: 7D | AD17: 7D | AG17: =COUNTIF(B17:AF17,"청") -> 1 | AH17: =COUNTIF(B17:AF17,"7D") -> 5 | AI17: 0 | AJ17: ='[1]2025.12.'!AL17 -> 46039 | AK17: =IFERROR(INDEX($B$3:$AF$5,1,MATCH("청",B17:AF17,0)),"") -> 46034 | AL17: =IFERROR(AK17+40,"") -> 46074
A18: 113 | E18: 7D | L18: 7D | S18: 7D | X18: 청 | Z18: 7D | AG18: =COUNTIF(B18:AF18,"청") -> 1 | AH18: =COUNTIF(B18:AF18,"7D") -> 4 | AI18: 0 | AJ18: ='[1]2025.12.'!AL18 -> 46048 | AK18: =IFERROR(INDEX($B$3:$AF$5,1,MATCH("청",B18:AF18,0)),"") -> 46045 | AL18: =IFERROR(AK18+40,"") -> 46085
A19: 114 | B19: 114편성(6Y, 12.19.~2.4.) | AG19: =COUNTIF(B19:AF19,"청") -> 0 | AH19: =COUNTIF(B19:AF19,"7D") -> 0 | AI19: 0 | AJ19: ='[1]2025.12.'!AL19 -> 46013 | AK19: =IFERROR(INDEX($B$3:$AF$5,1,MATCH("청",B19:AF19,0)),"") | AL19: =AJ19 -> 46013
A20: 115 | E20: 7D | L20: 7D | S20: 7D | U20: 청 | Z20: 7D | AG20: =COUNTIF(B20:AF20,"청") -> 1 | AH20: =COUNTIF(B20:AF20,"7D") -> 4 | AI20: 0 | AJ20: ='[1]2025.12.'!AL20 -> 46043 | AK20: =IFERROR(INDEX($B$3:$AF$5,1,MATCH("청",B20:AF20,0)),"") -> 46042 | AL20: =IFERROR(AK20+40,"") -> 46082
A21: 116 | C21: 7D | J21: 7D | Q21: 7D | X21: 7D | AE21: 7D | AG21: =COUNTIF(B21:AF21,"청") -> 0 | AH21: =COUNTIF(B21:AF21,"7D") -> 5 | AI21: 0 | AJ21: ='[1]2025.12.'!AL21 -> 46061 | AK21: =IFERROR(INDEX($B$3:$AF$5,1,MATCH("청",B21:AF21,0)),"") | AL21: =AJ21 -> 46061
A22: 117 | F22: 7D | M22: 7D | T22: 7D | W22: 청 | AA22: 7D | AG22: =COUNTIF(B22:AF22,"청") -> 1 | AH22: =COUNTIF(B22:AF22,"7D") -> 4 | AI22: 0 | AJ22: ='[1]2025.12.'!AL22 -> 46047 | AK22: =IFERROR(INDEX($B$3:$AF$5,1,MATCH("청",B22:AF22,0)),"") -> 46044 | AL22: =IFERROR(AK22+40,"") -> 46084
A23: 118 | D23: 7D | L23: 7D | N23: 청 | T23: 7D | AB23: 118(4M) | AG23: =COUNTIF(B23:AF23,"청") -> 1 | AH23: =COUNTIF(B23:AF23,"7D") -> 3 | AI23: 0 | AJ23: ='[1]2025.12.'!AL23 -> 46046 | AK23: =IFERROR(INDEX($B$3:$AF$5,1,MATCH("청",B23:AF23,0)),"") -> 46035 | AL23: =IFERROR(AK23+40,"") -> 46075 | AM23: 2/2, 대청소, 118편성
A24: 119 | G24: 7D | H24: 청 | N24: 7D | U24: 7D | AB24: 7D | AG24: =COUNTIF(B24:AF24,"청") -> 1 | AH24: =COUNTIF(B24:AF24,"7D") -> 4 | AI24: 0 | AJ24: ='[1]2025.12.'!AL24 -> 46034 | AK24: =IFERROR(INDEX($B$3:$AF$5,1,MATCH("청",B24:AF24,0)),"") -> 46029 | AL24: =IFERROR(AK24+40,"") -> 46069
A25: 120 | F25: 120(1Y) | J25: 청 | P25: 7D | W25: 7D | AD25: 7D | AG25: =COUNTIF(B25:AF25,"청") -> 1 | AH25: =COUNTIF(B25:AF25,"7D") -> 3 | AI25: 0 | AJ25: ='[1]2025.12.'!AL25 -> 46050 | AK25: =IFERROR(INDEX($B$3:$AF$5,1,MATCH("청",B25:AF25,0)),"") -> 46031 | AL25: =IFERROR(AK25+40,"") -> 46071
A26: 121 | G26: 7D | N26: 7D | T26: 청 | U26: 7D | AB26: 7D | AG26: =COUNTIF(B26:AF26,"청") -> 1 | AH26: =COUNTIF(B26:AF26,"7D") -> 4 | AI26: 0 | AJ26: ='[1]2025.12.'!AL26 -> 46042 | AK26: =IFERROR(INDEX($B$3:$AF$5,1,MATCH("청",B26:AF26,0)),"") -> 46041 | AL26: =IFERROR(AK26+40,"") -> 46081
A27: 122 | C27: 7D | K27: 7D | R27: 7D | Y27: 7D | AC27: 청 | AF27: 7D | AG27: =COUNTIF(B27:AF27,"청") -> 1 | AH27: =COUNTIF(B27:AF27,"7D") -> 5 | AI27: 0 | AJ27: ='[1]2025.12.'!AL27 -> 46053 | AK27: =IFERROR(INDEX($B$3:$AF$5,1,MATCH("청",B27:AF27,0)),"") -> 46050 | AL27: =IFERROR(AK27+40,"") -> 46090
A28: 123 | B28: 7D | G28: 청 | I28: 7D | P28: 7D | V28: 123(8M) | AB28: 청 | AG28: =COUNTIF(B28:AF28,"청") -> 2 | AH28: =COUNTIF(B28:AF28,"7D") -> 3 | AI28: 0 | AJ28: ='[1]2025.12.'!AL28 -> 46033 | AK28: 46049 | AL28: =IFERROR(AK28+40,"") -> 46089
A29: 7D | B29: =COUNTIF(B6:B28,"7D") -> 3 | C29: =COUNTIF(C6:C28,"7D") -> 3 | D29: =COUNTIF(D6:D28,"7D") -> 3 | E29: =COUNTIF(E6:E28,"7D") -> 3 | F29: =COUNTIF(F6:F28,"7D") -> 3 | G29: =COUNTIF(G6:G28,"7D") -> 2 | H29: =COUNTIF(H6:H28,"7D") -> 3 | I29: =COUNTIF(I6:I28,"7D") -> 3 | ... AF29: =COUNTIF(AF6:AF28,"7D") -> 2 | AH29: =SUM(B29:AF29) -> 89
A30: 4M | B30: 0 | C30: 1 | D30: 0 | E30: 0 | F30: 1 | G30: 1 | H30: 1 | I30: 1 | J30: 1 | K30: 0 | L30: 0 | M30: 1 | N30: 1 | O30: 1 | P30: 1 | Q30: 1 | R30: 0 | S30: 0 | T30: 1 | U30: 1 | V30: 1 | W30: 1 | X30: 1 | Y30: 0 | Z30: 0 | AA30: 1 | AB30: 1 | AC30: 1 | AD30: 1 | AE30: 1 | AF30: 0 | AI30: =SUM(B30:AF30) -> 21
A31: 대 | B31: =COUNTIF(B6:B28,"청") -> 0 | C31: =COUNTIF(C6:C28,"청") -> 1 | D31: =COUNTIF(D6:D28,"청") -> 0 | E31: =COUNTIF(E6:E28,"청") -> 0 | F31: =COUNTIF(F6:F28,"청") -> 1 | G31: =COUNTIF(G6:G28,"청") -> 1 | H31: =COUNTIF(H6:H28,"청") -> 1 | I31: =COUNTIF(I6:I28,"청") -> 1 | ... AF31: =COUNTIF(AF6:AF28,"청") -> 0 | AH31: =SUM(B31:AF31) -> 21
B34: 신정 | E34: 46023 | H34: 46023 | W34: 월상장비점검일
W35: 2, 6, 11월
W37: 대청소정비일
W38: 3, 11월

Sheet 2026.2.
A1: 전동차 정기검사 및 대청소 계획
A2: [2026.2.] [차량운영처 차량팀]
A3: 일자 | B3: 46054 | C3: 46055 | D3: 46056 | E3: 46057 | F3: 46058 | G3: 46059 | H3: 46060 | I3: 46061 | J3: 46062 | K3: 46063 | L3: 46064 | M3: 46065 | N3: 46066 | O3: 46067 | P3: 46068 | Q3: 46069 | R3: 46070 | S3: 46071 | T3: 46072 | U3: 46073 | V3: 46074 | W3: 46075 | X3: 46076 | Y3: 46077 | Z3: 46078 | AA3: 46079 | AB3: 46080 | AC3: 46081 | AG3: 소계
A5: 편성 요일 | B5: 46054 | C5: 46055 | D5: 46056 | E5: 46057 | F5: 46058 | G5: 46059 | H5: 46060 | I5: 46061 | J5: 46062 | K5: 46063 | L5: 46064 | M5: 46065 | N5: 46066 | O5: 46067 | P5: 46068 | Q5: 46069 | R5: 46070 | S5: 46071 | T5: 46072 | U5: 46073 | V5: 46074 | W5: 46075 | X5: 46076 | Y5: 46077 | Z5: 46078 | AA5: 46079 | AB5: 46080 | AC5: 46081 | AG5: 대 | AH5: 7D | AI5: 4M | AJ5: 시행 만료일 | AK5: 이달 시행일 | AL5: 다음 시행일
A6: 101 | B6: 7D | I6: 7D | P6: 7D | W6: 7D | AG6: =COUNTIF(B6:AF6,"청") -> 0 | AH6: =COUNTIF(B6:AF6,"7D") -> 4 | AI6: 0 | AJ6: ='2026.1.'!AL6 -> 46088 | AK6: =IFERROR(INDEX($B$3:$AF$5,1,MATCH("청",B6:AF6,0)),"") | AL6: =AJ6 -> 46088
A7: 102 | G7: 7D | N7: 7D | U7: 7D | AB7: 7D | AG7: =COUNTIF(B7:AF7,"청") -> 0 | AH7: =COUNTIF(B7:AF7,"7D") -> 4 | AI7: 0 | AJ7: ='2026.1.'!AL7 -> 46091 | AK7: =IFERROR(INDEX($B$3:$AF$5,1,MATCH("청",B7:AF7,0)),"") | AL7: =AJ7 -> 46091
A8: 103 | C8: 103(4M) | G8: 청 | M8: 7D | T8: 7D | AA8: 7D | AG8: =COUNTIF(B8:AF8,"청") -> 1 | AH8: =COUNTIF(B8:AF8,"7D") -> 3 | AI8: 0 | AJ8: ='2026.1.'!AL8 -> 46054 | AK8: =IFERROR(INDEX($B$3:$AF$5,1,MATCH("청",B8:AF8,0)),"") -> 46059 | AL8: =IFERROR(AK8+40,"") -> 46099
A9: 104 | H9: 7D | O9: 7D | T9: 청 | V9: 7D | AC9: 7D | AG9: =COUNTIF(B9:AF9,"청") -> 1 | AH9: =COUNTIF(B9:AF9,"7D") -> 4 | AI9: 0 | AJ9: ='2026.1.'!AL9 -> 46092 | AK9: =IFERROR(INDEX($B$3:$AF$5,1,MATCH("청",B9:AF9,0)),"") -> 46072 | AL9: =IFERROR(AK9+40,"") -> 46112
A10: 105 | E10: 청 | G10: 7D | N10: 7D | U10: 7D | AB10: 7D | AG10: =COUNTIF(B10:AF10,"청") -> 1 | AH10: =COUNTIF(B10:AF10,"7D") -> 4 | AI10: 0 | AJ10: ='2026.1.'!AL10 -> 46067 | AK10: =IFERROR(INDEX($B$3:$AF$5,1,MATCH("청",B10:AF10,0)),"") -> 46057 | AL10: =IFERROR(AK10+40,"") -> 46097
A11: 106 | D11: 7D | G11: 106(1Y) | M11: 청 | S11: 7D | Z11: 7D | AG11: =COUNTIF(B11:AF11,"청") -> 1 | AH11: =COUNTIF(B11:AF11,"7D") -> 3 | AI11: 0 | AJ11: ='2026.1.'!AL11 -> 46076 | AK11: =IFERROR(INDEX($B$3:$AF$5,1,MATCH("청",B11:AF11,0)),"") -> 46065 | AL11: =IFERROR(AK11+40,"") -> 46105
A12: 107 | E12: 7D | J12: 청 | L12: 7D | S12: 7D | Z12: 7D | AG12: =COUNTIF(B12:AF12,"청") -> 1 | AH12: =COUNTIF(B12:AF12,"7D") -> 4 | AI12: 0 | AJ12: ='2026.1.'!AL12 -> 46064 | AK12: =IFERROR(INDEX($B$3:$AF$5,1,MATCH("청",B12:AF12,0)),"") -> 46062 | AL12: =IFERROR(AK12+40,"") -> 46102
A13: 108 | D13: 7D | K13: 7D | Q13: 7D | X13: 7D | Z13: 청 | AG13: =COUNTIF(B13:AF13,"청") -> 1 | AH13: =COUNTIF(B13:AF13,"7D") -> 4 | AI13: 0 | AJ13: ='2026.1.'!AL13 -> 46083 | AK13: =IFERROR(INDEX($B$3:$AF$5,1,MATCH("청",B13:AF13,0)),"") -> 46078 | AL13: =IFERROR(AK13+40,"") -> 46118
A14: 109 | F14: 7D | M14: 109(8M) | X14: 청 | AB14: 7D | AG14: =COUNTIF(B14:AF14,"청") -> 1 | AH14: =COUNTIF(B14:AF14,"7D") -> 2 | AI14: 0 | AJ14: ='2026.1.'!AL14 -> 46070 | AK14: =IFERROR(INDEX($B$3:$AF$5,1,MATCH("청",B14:AF14,0)),"") -> 46076 | AL14: =IFERROR(AK14+40,"") -> 46116
A15: 110 | C15: 7D | J15: 7D | Q15: 7D | X15: 7D | Y15: 청 | AG15: =COUNTIF(B15:AF15,"청") -> 1 | AH15: =COUNTIF(B15:AF15,"7D") -> 4 | AI15: 0 | AJ15: ='2026.1.'!AL15 -> 46078 | AK15: =IFERROR(INDEX($B$3:$AF$5,1,MATCH("청",B15:AF15,0)),"") -> 46077 | AL15: =IFERROR(AK15+40,"") -> 46117
A16: 111 | E16: 7D | L16: 7D | R16: 7D | U16: 청 | Y16: 7D | AG16: =COUNTIF(B16:AF16,"청") -> 1 | AH16: =COUNTIF(B16:AF16,"7D") -> 4 | AI16: 0 | AJ16: ='2026.1.'!AL16 -> 46077 | AK16: =IFERROR(INDEX($B$3:$AF$5,1,MATCH("청",B16:AF16,0)),"") -> 46073 | AL16: =IFERROR(AK16+40,"") -> 46113
A17: 112 | F17: 7D | M17: 7D | T17: 7D | X17: 112(3Y-4M) | AB17: 청 | AG17: =COUNTIF(B17:AF17,"청") -> 1 | AH17: =COUNTIF(B17:AF17,"7D") -> 3 | AI17: 0 | AJ17: ='2026.1.'!AL17 -> 46074 | AK17: =IFERROR(INDEX($B$3:$AF$5,1,MATCH("청",B17:AF17,0)),"") -> 46080 | AL17: =IFERROR(AK17+40,"") -> 46120
A18: 113 | B18: 7D | I18: 7D | P18: 7D | W18: 7D | AG18: =COUNTIF(B18:AF18,"청") -> 0 | AH18: =COUNTIF(B18:AF18,"7D") -> 4 | AI18: 0 | AJ18: ='2026.1.'!AL18 -> 46085 | AK18: =IFERROR(INDEX($B$3:$AF$5,1,MATCH("청",B18:AF18,0)),"") | AL18: =AJ18 -> 46085
A19: 114 | B19: 114편성(6Y,~2.4.) | F19: 청 | L19: 7D | S19: 7D | Z19: 7D | AG19: =COUNTIF(B19:AF19,"청") -> 1 | AH19: =COUNTIF(B19:AF19,"7D") -> 3 | AI19: 0 | AJ19: ='2026.1.'!AL19 -> 46013 | AK19: =IFERROR(INDEX($B$3:$AF$5,1,MATCH("청",B19:AF19,0)),"") -> 46058 | AL19: =IFERROR(AK19+40,"") -> 46098
A20: 115 | B20: 7D | J20: 115편성(6Y, 2.9.~3.30.) | AG20: =COUNTIF(B20:AF20,"청") -> 0 | AH20: =COUNTIF(B20:AF20,"7D") -> 1 | AI20: 0 | AJ20: ='2026.1.'!AL20 -> 46082 | AK20: =IFERROR(INDEX($B$3:$AF$5,1,MATCH("청",B20:AF20,0)),"") | AL20: =AJ20 -> 46082
A21: 116 | D21: 청 | F21: 7D | N21: 7D | U21: 7D | AA21: 7D | AG21: =COUNTIF(B21:AF21,"청") -> 1 | AH21: =COUNTIF(B21:AF21,"7D") -> 4 | AI21: 0 | AJ21: ='2026.1.'!AL21 -> 46061 | AK21: =IFERROR(INDEX($B$3:$AF$5,1,MATCH("청",B21:AF21,0)),"") -> 46056 | AL21: =IFERROR(AK21+40,"") -> 46096
A22: 117 | C22: 7D | J22: 7D | Q22: 7D | X22: 7D | AA22: 청 | AG22: =COUNTIF(B22:AF22,"청") -> 1 | AH22: =COUNTIF(B22:AF22,"7D") -> 4 | AI22: 0 | AJ22: ='2026.1.'!AL22 -> 46084 | AK22: =IFERROR(INDEX($B$3:$AF$5,1,MATCH("청",B22:AF22,0)),"") -> 46079 | AL22: =IFERROR(AK22+40,"") -> 46119
A23: 118 | C23: 청 | H23: 7D | O23: 7D | V23: 7D | AC23: 7D | AG23: =COUNTIF(B23:AF23,"청") -> 1 | AH23: =COUNTIF(B23:AF23,"7D") -> 4 | AI23: 0 | AJ23: ='2026.1.'!AL23 -> 46075 | AK23: =IFERROR(INDEX($B$3:$AF$5,1,MATCH("청",B23:AF23,0)),"") -> 46055 | AL23: =IFERROR(AK23+40,"") -> 46095 | AM23: 2/2, 대청소, 118편성
A24: 119 | D24: 7D | K24: 7D | L24: 청 | R24: 7D | Y24: 7D | AG24: =COUNTIF(B24:AF24,"청") -> 1 | AH24: =COUNTIF(B24:AF24,"7D") -> 4 | AI24: 0 | AJ24: ='2026.1.'!AL24 -> 46069 | AK24: =IFERROR(INDEX($B$3:$AF$5,1,MATCH("청",B24:AF24,0)),"") -> 46064 | AL24: =IFERROR(AK24+40,"") -> 46104
A25: 120 | G25: 7D | K25: 청 | M25: 7D | T25: 7D | AA25: 7D | AG25: =COUNTIF(B25:AF25,"청") -> 1 | AH25: =COUNTIF(B25:AF25,"7D") -> 4 | AI25: 0 | AJ25: ='2026.1.'!AL25 -> 46071 | AK25: =IFERROR(INDEX($B$3:$AF$5,1,MATCH("청",B25:AF25,0)),"") -> 46063 | AL25: =IFERROR(AK25+40,"") -> 46103
A26: 121 | E26: 7D | K26: 7D | N26: 청 | R26: 7D | Y26: 7D | AG26: =COUNTIF(B26:AF26,"청") -> 1 | AH26: =COUNTIF(B26:AF26,"7D") -> 4 | AI26: 0 | AJ26: ='2026.1.'!AL26 -> 46081 | AK26: =IFERROR(INDEX($B$3:$AF$5,1,MATCH("청",B26:AF26,0)),"") -> 46066 | AL26: =IFERROR(AK26+40,"") -> 46106
A27: 122 | H27: 7D | O27: 7D | V27: 7D | AC27: 7D | AG27: =COUNTIF(B27:AF27,"청") -> 0 | AH27: =COUNTIF(B27:AF27,"7D") -> 4 | AI27: 0 | AJ27: ='2026.1.'!AL27 -> 46090 | AK27: =IFERROR(INDEX($B$3:$AF$5,1,MATCH("청",B27:AF27,0)),"") | AL27: =AJ27 -> 46090
A28: 123 | C28: 7D | J28: 7D | P28: 7D | W28: 7D | AG28: =COUNTIF(B28:AF28,"청") -> 0 | AH28: =COUNTIF(B28:AF28,"7D") -> 4 | AI28: 0 | AJ28: ='2026.1.'!AL28 -> 46089 | AK28: =IFERROR(INDEX($B$3:$AF$5,1,MATCH("청",B28:AF28,0)),"") | AL28: =AJ28 -> 46089
A29: 7D | B29: =COUNTIF(B6:B28,"7D") -> 3 | C29: =COUNTIF(C6:C28,"7D") -> 3 | D29: =COUNTIF(D6:D28,"7D") -> 3 | E29: =COUNTIF(E6:E28,"7D") -> 3 | F29: =COUNTIF(F6:F28,"7D") -> 3 | G29: =COUNTIF(G6:G28,"7D") -> 3 | H29: =COUNTIF(H6:H28,"7D") -> 3 | I29: =COUNTIF(I6:I28,"7D") -> 2 | ... AF29: =COUNTIF(AF6:AF28,"7D") -> 0 | AH29: =SUM(B29:AF29) -> 83
A30: 4M | B30: 0 | C30: 1 | D30: 1 | E30: 1 | F30: 1 | G30: 1 | H30: 0 | I30: 0 | J30: 1 | K30: 1 | L30: 1 | M30: 1 | N30: 1 | O30: 0 | P30: 0 | Q30: 0 | R30: 0 | S30: 0 | T30: 1 | U30: 1 | V30: 0 | W30: 0 | X30: 1 | Y30: 1 | Z30: 1 | AA30: 1 | AB30: 0 | AC30: 0 | AD30: 0 | AE30: 0 | AF30: 0 | AI30: =SUM(B30:AF30) -> 16
A31: 대 | B31: =COUNTIF(B6:B28,"청") -> 0 | C31: =COUNTIF(C6:C28,"청") -> 1 | D31: =COUNTIF(D6:D28,"청") -> 1 | E31: =COUNTIF(E6:E28,"청") -> 1 | F31: =COUNTIF(F6:F28,"청") -> 1 | G31: =COUNTIF(G6:G28,"청") -> 1 | H31: =COUNTIF(H6:H28,"청") -> 0 | I31: =COUNTIF(I6:I28,"청") -> 0 | ... AF31: =COUNTIF(AF6:AF28,"청") -> 0 | AH31: =SUM(B31:AF31) -> 17
AB32: 2.27.월상장비점검일
B34: 설연휴 | E34: 46069 | H34: 46069
B35: 설날 | E35: 46070 | H35: 46070 | W35: 월상장비점검일
B36: 설연휴 | E36: 46071 | H36: 46071 | W36: 2, 6, 11월
W38: 대청소정비일
W39: 3, 11월

Sheet 2026.3.
A1: 전동차 정기검사 및 대청소 계획
A2: [2026.3.] [차량운영처 차량팀]
A3: 일자 | B3: 46082 | C3: 46083 | D3: 46084 | E3: 46085 | F3: 46086 | G3: 46087 | H3: 46088 | I3: 46089 | J3: 46090 | K3: 46091 | L3: 46092 | M3: 46093 | N3: 46094 | O3: 46095 | P3: 46096 | Q3: 46097 | R3: 46098 | S3: 46099 | T3: 46100 | U3: 46101 | V3: 46102 | W3: 46103 | X3: 46104 | Y3: 46105 | Z3: 46106 | AA3: 46107 | AB3: 46108 | AC3: 46109 | AD3: 46110 | AE3: 46111 | AF3: 46112 | AG3: 소계
A5: 편성 요일 | B5: 46082 | C5: 46083 | D5: 46084 | E5: 46085 | F5: 46086 | G5: 46087 | H5: 46088 | I5: 46089 | J5: 46090 | K5: 46091 | L5: 46092 | M5: 46093 | N5: 46094 | O5: 46095 | P5: 46096 | Q5: 46097 | R5: 46098 | S5: 46099 | T5: 46100 | U5: 46101 | V5: 46102 | W5: 46103 | X5: 46104 | Y5: 46105 | Z5: 46106 | AA5: 46107 | AB5: 46108 | AC5: 46109 | AD5: 46110 | AE5: 46111 | AF5: 46112 | AG5: 대 | AH5: 7D | AI5: 4M | AJ5: 시행 만료일 | AK5: 이달 시행일 | AL5: 다음 시행일
A6: 101 | B6: 7D | J6: 101(8M) | N6: 청 | T6: 7D | AA6: 7D | AG6: =COUNTIF(B6:AF6,"청") -> 1 | AH6: =COUNTIF(B6:AF6,"7D") -> 3 | AI6: 0 | AJ6: ='2026.2.'!AL6 -> 46088 | AK6: =IFERROR(INDEX($B$3:$AF$5,1,MATCH("청",B6:AF6,0)),"") -> 46094 | AL6: =IFERROR(AK6+40,"") -> 46134
A7: 102 | G7: 7D | K7: 청 | N7: 7D | U7: 7D | AB7: 7D | AG7: =COUNTIF(B7:AF7,"청") -> 1 | AH7: =COUNTIF(B7:AF7,"7D") -> 4 | AI7: 0 | AJ7: ='2026.2.'!AL7 -> 46091 | AK7: =IFERROR(INDEX($B$3:$AF$5,1,MATCH("청",B7:AF7,0)),"") -> 46091 | AL7: =IFERROR(AK7+40,"") -> 46131
A8: 103 | F8: 7D | M8: 7D | R8: 청 | T8: 7D | AA8: 7D | AG8: =COUNTIF(B8:AF8,"청") -> 1 | AH8: =COUNTIF(B8:AF8,"7D") -> 4 | AI8: 0 | AJ8: ='2026.2.'!AL8 -> 46099 | AK8: =IFERROR(INDEX($B$3:$AF$5,1,MATCH("청",B8:AF8,0)),"") -> 46098 | AL8: =IFERROR(AK8+40,"") -> 46138
A9: 104 | H9: 7D | N9: 104(4M) | T9: 청 | Z9: 7D | AG9: =COUNTIF(B9:AF9,"청") -> 1 | AH9: =COUNTIF(B9:AF9,"7D") -> 2 | AI9: 0 | AJ9: ='2026.2.'!AL9 -> 46112 | AK9: =IFERROR(INDEX($B$3:$AF$5,1,MATCH("청",B9:AF9,0)),"") -> 46100 | AL9: =IFERROR(AK9+40,"") -> 46140
A10: 105 | G10: 7D | N10: 7D | Q10: 청 | U10: 7D | AB10: 7D | AG10: =COUNTIF(B10:AF10,"청") -> 1 | AH10: =COUNTIF(B10:AF10,"7D") -> 4 | AI10: 0 | AJ10: ='2026.2.'!AL10 -> 46097 | AK10: =IFERROR(INDEX($B$3:$AF$5,1,MATCH("청",B10:AF10,0)),"") -> 46097 | AL10: =IFERROR(AK10+40,"") -> 46137
A11: 106 | E11: 7D | L11: 7D | S11: 7D | X11: 청 | Y11: 7D | AE11: 7D | AG11: =COUNTIF(B11:AF11,"청") -> 1 | AH11: =COUNTIF(B11:AF11,"7D") -> 5 | AI11: 0 | AJ11: ='2026.2.'!AL11 -> 46105 | AK11: =IFERROR(INDEX($B$3:$AF$5,1,MATCH("청",B11:AF11,0)),"") -> 46104 | AL11: =IFERROR(AK11+40,"") -> 46144
A12: 107 | E12: 7D | L12: 7D | T12: 107(1Y) | Z12: 청 | AF12: 7D | AG12: =COUNTIF(B12:AF12,"청") -> 1 | AH12: =COUNTIF(B12:AF12,"7D") -> 3 | AI12: 0 | AJ12: ='2026.2.'!AL12 -> 46102 | AK12: =IFERROR(INDEX($B$3:$AF$5,1,MATCH("청",B12:AF12,0)),"") -> 46106 | AL12: =IFERROR(AK12+40,"") -> 46146
A13: 108 | C13: 7D | J13: 7D | Q13: 7D | X13: 7D | AD13: 7D | AG13: =COUNTIF(B13:AF13,"청") -> 0 | AH13: =COUNTIF(B13:AF13,"7D") -> 5 | AI13: 0 | AJ13: ='2026.2.'!AL13 -> 46118 | AK13: =IFERROR(INDEX($B$3:$AF$5,1,MATCH("청",B13:AF13,0)),"") | AL13: =AJ13 -> 46118
A14: 109 | G14: 7D | N14: 7D | U14: 7D | AB14: 7D | AE14: 청 | AG14: =COUNTIF(B14:AF14,"청") -> 1 | AH14: =COUNTIF(B14:AF14,"7D") -> 4 | AI14: 0 | AJ14: ='2026.2.'!AL14 -> 46116 | AK14: =IFERROR(INDEX($B$3:$AF$5,1,MATCH("청",B14:AF14,0)),"") -> 46111 | AL14: =IFERROR(AK14+40,"") -> 46151
A15: 110 | C15: 7D | J15: 7D | Q15: 7D | X15: 7D | Y15: 청 | AE15: 7D | AG15: =COUNTIF(B15:AF15,"청") -> 1 | AH15: =COUNTIF(B15:AF15,"7D") -> 5 | AI15: 0 | AJ15: ='2026.2.'!AL15 -> 46117 | AK15: =IFERROR(INDEX($B$3:$AF$5,1,MATCH("청",B15:AF15,0)),"") -> 46105 | AL15: =IFERROR(AK15+40,"") -> 46145
A16: 111 | D16: 7D | K16: 7D | R16: 7D | Y16: 7D | AA16: 청 | AF16: 7D | AG16: =COUNTIF(B16:AF16,"청") -> 1 | AH16: =COUNTIF(B16:AF16,"7D") -> 5 | AI16: 0 | AJ16: ='2026.2.'!AL16 -> 46113 | AK16: =IFERROR(INDEX($B$3:$AF$5,1,MATCH("청",B16:AF16,0)),"") -> 46107 | AL16: =IFERROR(AK16+40,"") -> 46147
A17: 112 | F17: 7D | M17: 7D | T17: 7D | AA17: 7D | AG17: =COUNTIF(B17:AF17,"청") -> 0 | AH17: =COUNTIF(B17:AF17,"7D") -> 4 | AI17: 0 | AJ17: ='2026.2.'!AL17 -> 46120 | AK17: =IFERROR(INDEX($B$3:$AF$5,1,MATCH("청",B17:AF17,0)),"") | AL17: =AJ17 -> 46120
A18: 113 | B18: 7D | D18: 청 | I18: 7D | P18: 7D | W18: 7D | AD18: 7D | AG18: =COUNTIF(B18:AF18,"청") -> 1 | AH18: =COUNTIF(B18:AF18,"7D") -> 5 | AI18: 0 | AJ18: ='2026.2.'!AL18 -> 46085 | AK18: =IFERROR(INDEX($B$3:$AF$5,1,MATCH("청",B18:AF18,0)),"") -> 46084 | AL18: =IFERROR(AK18+40,"") -> 46124
A19: 114 | D19: 7D | K19: 7D | R19: 7D | S19: 청 | Y19: 7D | AF19: 7D | AG19: =COUNTIF(B19:AF19,"청") -> 1 | AH19: =COUNTIF(B19:AF19,"7D") -> 5 | AI19: 0 | AJ19: ='2026.2.'!AL19 -> 46098 | AK19: =IFERROR(INDEX($B$3:$AF$5,1,MATCH("청",B19:AF19,0)),"") -> 46099 | AL19: =IFERROR(AK19+40,"") -> 46139
A20: 115 | B20: 115편성(6Y, 2.9.~3.30.) | AF20: 청 | AG20: =COUNTIF(B20:AF20,"청") -> 1 | AH20: =COUNTIF(B20:AF20,"7D") -> 0 | AI20: 0 | AJ20: ='2026.2.'!AL20 -> 46082 | AK20: =IFERROR(INDEX($B$3:$AF$5,1,MATCH("청",B20:AF20,0)),"") -> 46112 | AL20: =IFERROR(AK20+40,"") -> 46152
A21: 116 | E21: 7D | L21: 7D | M21: 청 | S21: 7D | Z21: 7D | AG21: =COUNTIF(B21:AF21,"청") -> 1 | AH21: =COUNTIF(B21:AF21,"7D") -> 4 | AI21: 0 | AJ21: ='2026.2.'!AL21 -> 46096 | AK21: =IFERROR(INDEX($B$3:$AF$5,1,MATCH("청",B21:AF21,0)),"") -> 46093 | AL21: =IFERROR(AK21+40,"") -> 46133
A22: 117 | C22: 7D | J22: 7D | Q22: 7D | X22: 7D | AG22: =COUNTIF(B22:AF22,"청") -> 0 | AH22: =COUNTIF(B22:AF22,"7D") -> 4 | AI22: 0 | AJ22: ='2026.2.'!AL22 -> 46119 | AK22: =IFERROR(INDEX($B$3:$AF$5,1,MATCH("청",B22:AF22,0)),"") | AL22: =AJ22 -> 46119
A23: 118 | H23: 7D | L23: 청 | O23: 7D | V23: 7D | AC23: 7D | AG23: =COUNTIF(B23:AF23,"청") -> 1 | AH23: =COUNTIF(B23:AF23,"7D") -> 4 | AI23: 0 | AJ23: ='2026.2.'!AL23 -> 46095 | AK23: =IFERROR(INDEX($B$3:$AF$5,1,MATCH("청",B23:AF23,0)),"") -> 46092 | AL23: =IFERROR(AK23+40,"") -> 46132
A24: 119 | D24: 7D | F24: 청 | K24: 7D | R24: 7D | Z24: 119(4M) | AG24: =COUNTIF(B24:AF24,"청") -> 1 | AH24: =COUNTIF(B24:AF24,"7D") -> 3 | AI24: 0 | AJ24: ='2026.2.'!AL24 -> 46104 | AK24: =IFERROR(INDEX($B$3:$AF$5,1,MATCH("청",B24:AF24,0)),"") -> 46086 | AL24: =IFERROR(AK24+40,"") -> 46126 | AM24: 119편성, 4/1, 대청소해야
A25: 120 | F25: 7D | M25: 7D | S25: 7D | U25: 청 | Z25: 7D | AG25: =COUNTIF(B25:AF25,"청") -> 1 | AH25: =COUNTIF(B25:AF25,"7D") -> 4 | AI25: 0 | AJ25: ='2026.2.'!AL25 -> 46103 | AK25: =IFERROR(INDEX($B$3:$AF$5,1,MATCH("청",B25:AF25,0)),"") -> 46101 | AL25: =IFERROR(AK25+40,"") -> 46141
A26: 121 | D26: 121(1Y) | J26: 청 | O26: 7D | V26: 7D | AC26: 7D | AG26: =COUNTIF(B26:AF26,"청") -> 1 | AH26: =COUNTIF(B26:AF26,"7D") -> 3 | AI26: 0 | AJ26: ='2026.2.'!AL26 -> 46106 | AK26: =IFERROR(INDEX($B$3:$AF$5,1,MATCH("청",B26:AF26,0)),"") -> 46090 | AL26: =IFERROR(AK26+40,"") -> 46130
A27: 122 | E27: 청 | H27: 7D | O27: 7D | V27: 7D | AC27: 7D | AG27: =COUNTIF(B27:AF27,"청") -> 1 | AH27: =COUNTIF(B27:AF27,"7D") -> 4 | AI27: 0 | AJ27: ='2026.2.'!AL27 -> 46090 | AK27: =IFERROR(INDEX($B$3:$AF$5,1,MATCH("청",B27:AF27,0)),"") -> 46085 | AL27: =IFERROR(AK27+40,"") -> 46125
A28: 123 | B28: 7D | G28: 청 | I28: 7D | P28: 7D | W28: 7D | AD28: 7D | AG28: =COUNTIF(B28:AF28,"청") -> 1 | AH28: =COUNTIF(B28:AF28,"7D") -> 5 | AI28: 0 | AJ28: ='2026.2.'!AL28 -> 46089 | AK28: =IFERROR(INDEX($B$3:$AF$5,1,MATCH("청",B28:AF28,0)),"") -> 46087 | AL28: =IFERROR(AK28+40,"") -> 46127
A29: 7D | B29: =COUNTIF(B6:B28,"7D") -> 3 | C29: =COUNTIF(C6:C28,"7D") -> 3 | D29: =COUNTIF(D6:D28,"7D") -> 3 | E29: =COUNTIF(E6:E28,"7D") -> 3 | F29: =COUNTIF(F6:F28,"7D") -> 3 | G29: =COUNTIF(G6:G28,"7D") -> 3 | H29: =COUNTIF(H6:H28,"7D") -> 3 | I29: =COUNTIF(I6:I28,"7D") -> 2 | ... AF29: =COUNTIF(AF6:AF28,"7D") -> 3 | AH29: =SUM(B29:AF29) -> 89
A30: 4M | B30: 0 | C30: 0 | D30: 1 | E30: 1 | F30: 1 | G30: 1 | H30: 0 | I30: 0 | J30: 1 | K30: 1 | L30: 1 | M30: 1 | N30: 1 | O30: 0 | P30: 0 | Q30: 1 | R30: 1 | S30: 1 | T30: 1 | U30: 1 | V30: 0 | W30: 0 | X30: 1 | Y30: 1 | Z30: 1 | AA30: 1 | AB30: 1 | AC30: 0 | AD30: 0 | AE30: 1 | AF30: 1 | AI30: =SUM(B30:AF30) -> 21
A31: 대 | B31: =COUNTIF(B6:B28,"청") -> 0 | C31: =COUNTIF(C6:C28,"청") -> 0 | D31: =COUNTIF(D6:D28,"청") -> 1 | E31: =COUNTIF(E6:E28,"청") -> 1 | F31: =COUNTIF(F6:F28,"청") -> 1 | G31: =COUNTIF(G6:G28,"청") -> 1 | H31: =COUNTIF(H6:H28,"청") -> 0 | I31: =COUNTIF(I6:I28,"청") -> 0 | ... AF31: =COUNTIF(AF6:AF28,"청") -> 1 | AH31: =SUM(B31:AF31) -> 20
AB32: 3/27, 대청소정비일
B34: 3∙1 | E34: 46082 | H34: 46082
B35: 대체공휴일 | E35: 46083 | H35: 46083 | X35: 월상장비점검일
X36: 2, 6, 11월
X38: 대청소정비일
X39: 3, 11월

Sheet 2026.4.
A1: 전동차 정기검사 및 대청소 계획
A2: [2026.4.] [차량운영처 차량팀]
A3: 일자 | B3: 46113 | C3: 46114 | D3: 46115 | E3: 46116 | F3: 46117 | G3: 46118 | H3: 46119 | I3: 46120 | J3: 46121 | K3: 46122 | L3: 46123 | M3: 46124 | N3: 46125 | O3: 46126 | P3: 46127 | Q3: 46128 | R3: 46129 | S3: 46130 | T3: 46131 | U3: 46132 | V3: 46133 | W3: 46134 | X3: 46135 | Y3: 46136 | Z3: 46137 | AA3: 46138 | AB3: 46139 | AC3: 46140 | AD3: 46141 | AE3: 46142 | AG3: 소계
A5: 편성 요일 | B5: 46113 | C5: 46114 | D5: 46115 | E5: 46116 | F5: 46117 | G5: 46118 | H5: 46119 | I5: 46120 | J5: 46121 | K5: 46122 | L5: 46123 | M5: 46124 | N5: 46125 | O5: 46126 | P5: 46127 | Q5: 46128 | R5: 46129 | S5: 46130 | T5: 46131 | U5: 46132 | V5: 46133 | W5: 46134 | X5: 46135 | Y5: 46136 | Z5: 46137 | AA5: 46138 | AB5: 46139 | AC5: 46140 | AD5: 46141 | AE5: 46142 | AG5: 대 | AH5: 7D | AI5: 4M | AJ5: 시행 만료일 | AK5: 이달 시행일 | AL5: 다음 시행일
A6: 101 | C6: 7D | J6: 7D | Q6: 7D | U6: 청 | X6: 7D | AE6: 7D | AG6: =COUNTIF(B6:AF6,"청") -> 1 | AH6: =COUNTIF(B6:AF6,"7D") -> 5 | AI6: 0 | AJ6: ='2026.3.'!AL6 -> 46134 | AK6: =IFERROR(INDEX($B$3:$AF$5,1,MATCH("청",B6:AF6,0)),"") -> 46132 | AL6: =IFERROR(AK6+40,"") -> 46172
A7: 102 | D7: 7D | H7: 청 | J7: 7D | Q7: 7D | W7: 102(8M) | AC7: 청 | AG7: =COUNTIF(B7:AF7,"청") -> 2 | AH7: =COUNTIF(B7:AF7,"7D") -> 3 | AI7: 0 | AJ7: ='2026.3.'!AL7 -> 46131 | AK7: 46140 | AL7: =IFERROR(AK7+40,"") -> 46180
A8: 103 | C8: 7D | I8: 청 | J8: 7D | Q8: 7D | X8: 7D | AE8: 7D | AG8: =COUNTIF(B8:AF8,"청") -> 1 | AH8: =COUNTIF(B8:AF8,"7D") -> 5 | AI8: 0 | AJ8: ='2026.3.'!AL8 -> 46138 | AK8: =IFERROR(INDEX($B$3:$AF$5,1,MATCH("청",B8:AF8,0)),"") -> 46120 | AL8: =IFERROR(AK8+40,"") -> 46160
A9: 104 | B9: 7D | I9: 7D | P9: 7D | V9: 청 | W9: 7D | AD9: 7D | AG9: =COUNTIF(B9:AF9,"청") -> 1 | AH9: =COUNTIF(B9:AF9,"7D") -> 5 | AI9: 0 | AJ9: ='2026.3.'!AL9 -> 46140 | AK9: =IFERROR(INDEX($B$3:$AF$5,1,MATCH("청",B9:AF9,0)),"") -> 46133 | AL9: =IFERROR(AK9+40,"") -> 46173
A10: 105 | D10: 7D | K10: 7D | P10: 청 | R10: 7D | Y10: 7D | AC10: 105(4M) | AG10: =COUNTIF(B10:AF10,"청") -> 1 | AH10: =COUNTIF(B10:AF10,"7D") -> 4 | AI10: 0 | AJ10: ='2026.3.'!AL10 -> 46137 | AK10: =IFERROR(INDEX($B$3:$AF$5,1,MATCH("청",B10:AF10,0)),"") -> 46127 | AL10: =IFERROR(AK10+40,"") -> 46167 | AM10: 105편성, 5/6, 대청소
A11: 106 | G11: 7D | N11: 7D | U11: 7D | Y11: 청 | AA11: 7D | AG11: =COUNTIF(B11:AF11,"청") -> 1 | AH11: =COUNTIF(B11:AF11,"7D") -> 4 | AI11: 0 | AJ11: ='2026.3.'!AL11 -> 46144 | AK11: =IFERROR(INDEX($B$3:$AF$5,1,MATCH("청",B11:AF11,0)),"") -> 46136 | AL11: =IFERROR(AK11+40,"") -> 46176
A12: 107 | G12: 7D | N12: 7D | U12: 7D | AB12: 7D | AD12: 청 | AG12: =COUNTIF(B12:AF12,"청") -> 1 | AH12: =COUNTIF(B12:AF12,"7D") -> 4 | AI12: 0 | AJ12: ='2026.3.'!AL12 -> 46146 | AK12: =IFERROR(INDEX($B$3:$AF$5,1,MATCH("청",B12:AF12,0)),"") -> 46141 | AL12: =IFERROR(AK12+40,"") -> 46181
A13: 108 | C13: 청 | F13: 7D | M13: 7D | T13: 7D | AA13: 7D | AG13: =COUNTIF(B13:AF13,"청") -> 1 | AH13: =COUNTIF(B13:AF13,"7D") -> 4 | AI13: 0 | AJ13: ='2026.3.'!AL13 -> 46118 | AK13: =IFERROR(INDEX($B$3:$AF$5,1,MATCH("청",B13:AF13,0)),"") -> 46114 | AL13: =IFERROR(AK13+40,"") -> 46154
A14: 109 | D14: 7D | K14: 7D | S14: 7D | Z14: 7D | AB14: 청 | AG14: =COUNTIF(B14:AF14,"청") -> 1 | AH14: =COUNTIF(B14:AF14,"7D") -> 4 | AI14: 0 | AJ14: ='2026.3.'!AL14 -> 46151 | AK14: =IFERROR(INDEX($B$3:$AF$5,1,MATCH("청",B14:AF14,0)),"") -> 46139 | AL14: =IFERROR(AK14+40,"") -> 46179
A15: 110 | F15: 7D | K15: 110(8M) | Q15: 청 | W15: 7D | AD15: 7D | AG15: =COUNTIF(B15:AF15,"청") -> 1 | AH15: =COUNTIF(B15:AF15,"7D") -> 3 | AI15: 0 | AJ15: ='2026.3.'!AL15 -> 46145 | AK15: =IFERROR(INDEX($B$3:$AF$5,1,MATCH("청",B15:AF15,0)),"") -> 46128 | AL15: =IFERROR(AK15+40,"") -> 46168
A16: 111 | H16: 7D | O16: 7D | V16: 7D | AB16: 7D | AE16: 청 | AG16: =COUNTIF(B16:AF16,"청") -> 1 | AH16: =COUNTIF(B16:AF16,"7D") -> 4 | AI16: 0 | AJ16: ='2026.3.'!AL16 -> 46147 | AK16: =IFERROR(INDEX($B$3:$AF$5,1,MATCH("청",B16:AF16,0)),"") -> 46142 | AL16: =IFERROR(AK16+40,"") -> 46182
A17: 112 | C17: 7D | D17: 청 | I17: 7D | P17: 7D | X17: 7D | AE17: 7D | AG17: =COUNTIF(B17:AF17,"청") -> 1 | AH17: =COUNTIF(B17:AF17,"7D") -> 5 | AI17: 0 | AJ17: ='2026.3.'!AL17 -> 46120 | AK17: =IFERROR(INDEX($B$3:$AF$5,1,MATCH("청",B17:AF17,0)),"") -> 46115 | AL17: =IFERROR(AK17+40,"") -> 46155
A18: 113 | G18: 113(3Y-4M) | K18: 청 | R18: 7D | Y18: 7D | AG18: =COUNTIF(B18:AF18,"청") -> 1 | AH18: =COUNTIF(B18:AF18,"7D") -> 2 | AI18: 0 | AJ18: ='2026.3.'!AL18 -> 46124 | AK18: =IFERROR(INDEX($B$3:$AF$5,1,MATCH("청",B18:AF18,0)),"") -> 46122 | AL18: =IFERROR(AK18+40,"") -> 46162
A19: 114 | H19: 7D | O19: 7D | V19: 7D | X19: 청 | AC19: 7D | AG19: =COUNTIF(B19:AF19,"청") -> 1 | AH19: =COUNTIF(B19:AF19,"7D") -> 4 | AI19: 0 | AJ19: ='2026.3.'!AL19 -> 46139 | AK19: =IFERROR(INDEX($B$3:$AF$5,1,MATCH("청",B19:AF19,0)),"") -> 46135 | AL19: =IFERROR(AK19+40,"") -> 46175
A20: 115 | G20: 7D | N20: 7D | U20: 7D | AB20: 7D | AG20: =COUNTIF(B20:AF20,"청") -> 0 | AH20: =COUNTIF(B20:AF20,"7D") -> 4 | AI20: 0 | AJ20: ='2026.3.'!AL20 -> 46152 | AK20: =IFERROR(INDEX($B$3:$AF$5,1,MATCH("청",B20:AF20,0)),"") | AL20: =AJ20 -> 46152
A21: 116 | C21: 116편성(6Y, 4.2.~5.20.) | AG21: =COUNTIF(B21:AF21,"청") -> 0 | AH21: =COUNTIF(B21:AF21,"7D") -> 0 | AI21: 0 | AJ21: ='2026.3.'!AL21 -> 46133 | AK21: =IFERROR(INDEX($B$3:$AF$5,1,MATCH("청",B21:AF21,0)),"") | AL21: =AJ21 -> 46133
A22: 117 | B22: 117(8M) | G22: 청 | K22: 7D | R22: 7D | Y22: 7D | AG22: =COUNTIF(B22:AF22,"청") -> 1 | AH22: =COUNTIF(B22:AF22,"7D") -> 3 | AI22: 0 | AJ22: ='2026.3.'!AL22 -> 46119 | AK22: =IFERROR(INDEX($B$3:$AF$5,1,MATCH("청",B22:AF22,0)),"") -> 46118 | AL22: =IFERROR(AK22+40,"") -> 46158
A23: 118 | E23: 7D | L23: 7D | O23: 청 | S23: 7D | Z23: 7D | AG23: =COUNTIF(B23:AF23,"청") -> 1 | AH23: =COUNTIF(B23:AF23,"7D") -> 4 | AI23: 0 | AJ23: ='2026.3.'!AL23 -> 46132 | AK23: =IFERROR(INDEX($B$3:$AF$5,1,MATCH("청",B23:AF23,0)),"") -> 46126 | AL23: =IFERROR(AK23+40,"") -> 46166
A24: 119 | B24: 청 | H24: 7D | O24: 7D | V24: 7D | AC24: 7D | AG24: =COUNTIF(B24:AF24,"청") -> 1 | AH24: =COUNTIF(B24:AF24,"7D") -> 4 | AI24: 0 | AJ24: ='2026.3.'!AL24 -> 46126 | AK24: =IFERROR(INDEX($B$3:$AF$5,1,MATCH("청",B24:AF24,0)),"") -> 46113 | AL24: =IFERROR(AK24+40,"") -> 46153 | AM24: 119편성, 4/1, 대청소해야
A25: 120 | B25: 7D | I25: 7D | P25: 7D | R25: 청 | W25: 7D | AD25: 7D | AG25: =COUNTIF(B25:AF25,"청") -> 1 | AH25: =COUNTIF(B25:AF25,"7D") -> 5 | AI25: 0 | AJ25: ='2026.3.'!AL25 -> 46141 | AK25: =IFERROR(INDEX($B$3:$AF$5,1,MATCH("청",B25:AF25,0)),"") -> 46129 | AL25: =IFERROR(AK25+40,"") -> 46169
A26: 121 | E26: 7D | L26: 7D | N26: 청 | S26: 7D | Z26: 7D | AG26: =COUNTIF(B26:AF26,"청") -> 1 | AH26: =COUNTIF(B26:AF26,"7D") -> 4 | AI26: 0 | AJ26: ='2026.3.'!AL26 -> 46130 | AK26: =IFERROR(INDEX($B$3:$AF$5,1,MATCH("청",B26:AF26,0)),"") -> 46125 | AL26: =IFERROR(AK26+40,"") -> 46165
A27: 122 | E27: 7D | L27: 7D | Q27: 122(1Y) | W27: 청 | AC27: 7D | AG27: =COUNTIF(B27:AF27,"청") -> 1 | AH27: =COUNTIF(B27:AF27,"7D") -> 3 | AI27: 0 | AJ27: ='2026.3.'!AL27 -> 46125 | AK27: =IFERROR(INDEX($B$3:$AF$5,1,MATCH("청",B27:AF27,0)),"") -> 46134 | AL27: =IFERROR(AK27+40,"") -> 46174
A28: 123 | F28: 7D | J28: 청 | M28: 7D | T28: 7D | AA28: 7D | AG28: =COUNTIF(B28:AF28,"청") -> 1 | AH28: =COUNTIF(B28:AF28,"7D") -> 4 | AI28: 0 | AJ28: ='2026.3.'!AL28 -> 46127 | AK28: =IFERROR(INDEX($B$3:$AF$5,1,MATCH("청",B28:AF28,0)),"") -> 46121 | AL28: =IFERROR(AK28+40,"") -> 46161
A29: 7D | B29: =COUNTIF(B6:B28,"7D") -> 2 | C29: =COUNTIF(C6:C28,"7D") -> 3 | D29: =COUNTIF(D6:D28,"7D") -> 3 | E29: =COUNTIF(E6:E28,"7D") -> 3 | F29: =COUNTIF(F6:F28,"7D") -> 3 | G29: =COUNTIF(G6:G28,"7D") -> 3 | H29: =COUNTIF(H6:H28,"7D") -> 3 | I29: =COUNTIF(I6:I28,"7D") -> 3 | ... AF29: =COUNTIF(AF6:AF28,"7D") -> 0 | AH29: =SUM(B29:AF29) -> 87
A30: 4M | B30: 1 | C30: 1 | D30: 1 | E30: 0 | F30: 0 | G30: 1 | H30: 1 | I30: 1 | J30: 1 | K30: 1 | L30: 0 | M30: 0 | N30: 1 | O30: 1 | P30: 1 | Q30: 1 | R30: 1 | S30: 0 | T30: 0 | U30: 1 | V30: 1 | W30: 1 | X30: 1 | Y30: 1 | Z30: 0 | AA30: 0 | AB30: 1 | AC30: 1 | AD30: 1 | AE30: 1 | AF30: 0 | AI30: =SUM(B30:AF30) -> 22
A31: 대 | B31: =COUNTIF(B6:B28,"청") -> 1 | C31: =COUNTIF(C6:C28,"청") -> 1 | D31: =COUNTIF(D6:D28,"청") -> 1 | E31: =COUNTIF(E6:E28,"청") -> 0 | F31: =COUNTIF(F6:F28,"청") -> 0 | G31: =COUNTIF(G6:G28,"청") -> 1 | H31: =COUNTIF(H6:H28,"청") -> 1 | I31: =COUNTIF(I6:I28,"청") -> 1 | ... AF31: =COUNTIF(AF6:AF28,"청") -> 0 | AH31: =SUM(B31:AF31) -> 22
B34: 휴일없음
X35: 월상장비점검일
X36: 2, 6, 11월
X38: 대청소정비일
X39: 3, 11월

Sheet 2026.5.
A1: 전동차 정기검사 및 대청소 계획
A2: [2026.5.] [차량운영처 차량팀]
A3: 일자 | B3: 46143 | C3: 46144 | D3: 46145 | E3: 46146 | F3: 46147 | G3: 46148 | H3: 46149 | I3: 46150 | J3: 46151 | K3: 46152 | L3: 46153 | M3: 46154 | N3: 46155 | O3: 46156 | P3: 46157 | Q3: 46158 | R3: 46159 | S3: 46160 | T3: 46161 | U3: 46162 | V3: 46163 | W3: 46164 | X3: 46165 | Y3: 46166 | Z3: 46167 | AA3: 46168 | AB3: 46169 | AC3: 46170 | AD3: 46171 | AE3: 46172 | AF3: 46173 | AG3: 소계
A5: 편성 요일 | B5: 46143 | C5: 46144 | D5: 46145 | E5: 46146 | F5: 46147 | G5: 46148 | H5: 46149 | I5: 46150 | J5: 46151 | K5: 46152 | L5: 46153 | M5: 46154 | N5: 46155 | O5: 46156 | P5: 46157 | Q5: 46158 | R5: 46159 | S5: 46160 | T5: 46161 | U5: 46162 | V5: 46163 | W5: 46164 | X5: 46165 | Y5: 46166 | Z5: 46167 | AA5: 46168 | AB5: 46169 | AC5: 46170 | AD5: 46171 | AE5: 46172 | AF5: 46173 | AG5: 대 | AH5: 7D | AI5: 4M | AJ5: 시행 만료일 | AK5: 이달 시행일 | AL5: 다음 시행일
A6: 101 | H6: 7D | O6: 7D | V6: 7D | AA6: 청 | AC6: 7D | AG6: =COUNTIF(B6:AF6,"청") -> 1 | AH6: =COUNTIF(B6:AF6,"7D") -> 4 | AI6: 0 | AJ6: ='2026.4.'!AL6 -> 46172 | AK6: =IFERROR(INDEX($B$3:$AF$5,1,MATCH("청",B6:AF6,0)),"") -> 46168 | AL6: =IFERROR(AK6+40,"") -> 46208
A7: 102 | E7: 7D | L7: 7D | S7: 7D | Z7: 7D | AG7: =COUNTIF(B7:AF7,"청") -> 0 | AH7: =COUNTIF(B7:AF7,"7D") -> 4 | AI7: 0 | AJ7: ='2026.4.'!AL7 -> 46180 | AK7: =IFERROR(INDEX($B$3:$AF$5,1,MATCH("청",B7:AF7,0)),"") | AL7: =AJ7 -> 46180
A8: 103 | H8: 7D | O8: 7D | V8: 7D | AB8: 7D | AC8: 청 | AG8: =COUNTIF(B8:AF8,"청") -> 1 | AH8: =COUNTIF(B8:AF8,"7D") -> 4 | AI8: 0 | AJ8: ='2026.4.'!AL8 -> 46160 | AK8: =IFERROR(INDEX($B$3:$AF$5,1,MATCH("청",B8:AF8,0)),"") -> 46170 | AL8: =IFERROR(AK8+40,"") -> 46210
A9: 104 | G9: 7D | N9: 7D | U9: 7D | AB9: 7D | AG9: =COUNTIF(B9:AF9,"청") -> 0 | AH9: =COUNTIF(B9:AF9,"7D") -> 4 | AI9: 0 | AJ9: ='2026.4.'!AL9 -> 46173 | AK9: =IFERROR(INDEX($B$3:$AF$5,1,MATCH("청",B9:AF9,0)),"") | AL9: =AJ9 -> 46173
A10: 105 | B10: 105(4M) | G10: 청 | L10: 7D | S10: 7D | Z10: 7D | AG10: =COUNTIF(B10:AF10,"청") -> 1 | AH10: =COUNTIF(B10:AF10,"7D") -> 3 | AI10: 0 | AJ10: ='2026.4.'!AL10 -> 46167 | AK10: =IFERROR(INDEX($B$3:$AF$5,1,MATCH("청",B10:AF10,0)),"") -> 46148 | AL10: =IFERROR(AK10+40,"") -> 46188 | AM10: 105편성, 5/6, 대청소
A11: 106 | D11: 7D | K11: 7D | R11: 7D | Y11: 7D | AF11: 7D | AG11: =COUNTIF(B11:AF11,"청") -> 0 | AH11: =COUNTIF(B11:AF11,"7D") -> 5 | AI11: 0 | AJ11: ='2026.4.'!AL11 -> 46176 | AK11: =IFERROR(INDEX($B$3:$AF$5,1,MATCH("청",B11:AF11,0)),"") | AL11: =AJ11 -> 46176
A12: 107 | E12: 7D | L12: 7D | S12: 7D | Y12: 7D | AF12: 7D | AG12: =COUNTIF(B12:AF12,"청") -> 0 | AH12: =COUNTIF(B12:AF12,"7D") -> 5 | AI12: 0 | AJ12: ='2026.4.'!AL12 -> 46181 | AK12: =IFERROR(INDEX($B$3:$AF$5,1,MATCH("청",B12:AF12,0)),"") | AL12: =AJ12 -> 46181
A13: 108 | C13: 7D | J13: 7D | Q13: 7D | T13: 108(1Y) | AB13: 청 | AG13: =COUNTIF(B13:AF13,"청") -> 1 | AH13: =COUNTIF(B13:AF13,"7D") -> 3 | AI13: 0 | AJ13: ='2026.4.'!AL13 -> 46154 | AK13: =IFERROR(INDEX($B$3:$AF$5,1,MATCH("청",B13:AF13,0)),"") -> 46169 | AL13: =IFERROR(AK13+40,"") -> 46209
A14: 109 | C14: 7D | J14: 7D | Q14: 7D | X14: 7D | AE14: 7D | AG14: =COUNTIF(B14:AF14,"청") -> 0 | AH14: =COUNTIF(B14:AF14,"7D") -> 5 | AI14: 0 | AJ14: ='2026.4.'!AL14 -> 46179 | AK14: =IFERROR(INDEX($B$3:$AF$5,1,MATCH("청",B14:AF14,0)),"") | AL14: =AJ14 -> 46179
A15: 110 | G15: 7D | N15: 7D | U15: 7D | AC15: 7D | AD15: 청 | AG15: =COUNTIF(B15:AF15,"청") -> 1 | AH15: =COUNTIF(B15:AF15,"7D") -> 4 | AI15: 0 | AJ15: ='2026.4.'!AL15 -> 46168 | AK15: =IFERROR(INDEX($B$3:$AF$5,1,MATCH("청",B15:AF15,0)),"") -> 46171 | AL15: =IFERROR(AK15+40,"") -> 46211
A16: 111 | E16: 7D | M16: 111(8M) | T16: 청 | W16: 7D | AD16: 7D | AG16: =COUNTIF(B16:AF16,"청") -> 1 | AH16: =COUNTIF(B16:AF16,"7D") -> 3 | AI16: 0 | AJ16: ='2026.4.'!AL16 -> 46182 | AK16: =IFERROR(INDEX($B$3:$AF$5,1,MATCH("청",B16:AF16,0)),"") -> 46161 | AL16: =IFERROR(AK16+40,"") -> 46201
A17: 112 | H17: 7D | L17: 청 | O17: 7D | V17: 7D | AC17: 7D | AG17: =COUNTIF(B17:AF17,"청") -> 1 | AH17: =COUNTIF(B17:AF17,"7D") -> 4 | AI17: 0 | AJ17: ='2026.4.'!AL17 -> 46155 | AK17: =IFERROR(INDEX($B$3:$AF$5,1,MATCH("청",B17:AF17,0)),"") -> 46153 | AL17: =IFERROR(AK17+40,"") -> 46193
A18: 113 | B18: 7D | I18: 7D | O18: 청 | P18: 7D | W18: 7D | AD18: 7D | AG18: =COUNTIF(B18:AF18,"청") -> 1 | AH18: =COUNTIF(B18:AF18,"7D") -> 5 | AI18: 0 | AJ18: ='2026.4.'!AL18 -> 46162 | AK18: =IFERROR(INDEX($B$3:$AF$5,1,MATCH("청",B18:AF18,0)),"") -> 46156 | AL18: =IFERROR(AK18+40,"") -> 46196
A19: 114 | F19: 7D | M19: 7D | T19: 7D | AB19: 114(6Y-4M) | AG19: =COUNTIF(B19:AF19,"청") -> 0 | AH19: =COUNTIF(B19:AF19,"7D") -> 3 | AI19: 0 | AJ19: ='2026.4.'!AL19 -> 46175 | AK19: =IFERROR(INDEX($B$3:$AF$5,1,MATCH("청",B19:AF19,0)),"") | AL19: =AJ19 -> 46175 | AM19: 114편성, 6/2, 대청소해야
A20: 115 | D20: 7D | E20: 청 | K20: 7D | R20: 7D | Y20: 7D | AF20: 7D | AG20: =COUNTIF(B20:AF20,"청") -> 1 | AH20: =COUNTIF(B20:AF20,"7D") -> 5 | AI20: 0 | AJ20: ='2026.4.'!AL20 -> 46152 | AK20: =IFERROR(INDEX($B$3:$AF$5,1,MATCH("청",B20:AF20,0)),"") -> 46146 | AL20: =IFERROR(AK20+40,"") -> 46186
A21: 116 | B21: 116편성(6Y, 4.2.~5.20.) | V21: 청 | AB21: 7D | AG21: =COUNTIF(B21:AF21,"청") -> 1 | AH21: =COUNTIF(B21:AF21,"7D") -> 1 | AI21: 0 | AJ21: ='2026.4.'!AL21 -> 46133 | AK21: =IFERROR(INDEX($B$3:$AF$5,1,MATCH("청",B21:AF21,0)),"") -> 46163 | AL21: =IFERROR(AK21+40,"") -> 46203
A22: 117 | B22: 7D | H22: 청 | I22: 7D | P22: 7D | W22: 7D | AB22: 117편성(6Y,5.27.~7.10.) | AG22: =COUNTIF(B22:AF22,"청") -> 1 | AH22: =COUNTIF(B22:AF22,"7D") -> 4 | AI22: 0 | AJ22: ='2026.4.'!AL22 -> 46158 | AK22: =IFERROR(INDEX($B$3:$AF$5,1,MATCH("청",B22:AF22,0)),"") -> 46149 | AL22: =IFERROR(AK22+40,"") -> 46189
A23: 118 | C23: 7D | J23: 7D | P23: 청 | Q23: 7D | X23: 7D | AE23: 7D | AG23: =COUNTIF(B23:AF23,"청") -> 1 | AH23: =COUNTIF(B23:AF23,"7D") -> 5 | AI23: 0 | AJ23: ='2026.4.'!AL23 -> 46166 | AK23: =IFERROR(INDEX($B$3:$AF$5,1,MATCH("청",B23:AF23,0)),"") -> 46157 | AL23: =IFERROR(AK23+40,"") -> 46197
A24: 119 | F24: 7D | I24: 청 | M24: 7D | T24: 7D | AA24: 7D | AG24: =COUNTIF(B24:AF24,"청") -> 1 | AH24: =COUNTIF(B24:AF24,"7D") -> 4 | AI24: 0 | AJ24: ='2026.4.'!AL24 -> 46153 | AK24: =IFERROR(INDEX($B$3:$AF$5,1,MATCH("청",B24:AF24,0)),"") -> 46150 | AL24: =IFERROR(AK24+40,"") -> 46190
A25: 120 | G25: 120(4M) | M25: 청 | T25: 7D | AA25: 7D | AG25: =COUNTIF(B25:AF25,"청") -> 1 | AH25: =COUNTIF(B25:AF25,"7D") -> 2 | AI25: 0 | AJ25: ='2026.4.'!AL25 -> 46169 | AK25: =IFERROR(INDEX($B$3:$AF$5,1,MATCH("청",B25:AF25,0)),"") -> 46154 | AL25: =IFERROR(AK25+40,"") -> 46194
A26: 121 | B26: 7D | I26: 7D | P26: 7D | U26: 청 | X26: 7D | AE26: 7D | AG26: =COUNTIF(B26:AF26,"청") -> 1 | AH26: =COUNTIF(B26:AF26,"7D") -> 5 | AI26: 0 | AJ26: ='2026.4.'!AL26 -> 46165 | AK26: =IFERROR(INDEX($B$3:$AF$5,1,MATCH("청",B26:AF26,0)),"") -> 46162 | AL26: =IFERROR(AK26+40,"") -> 46202
A27: 122 | F27: 7D | M27: 7D | U27: 7D | AA27: 7D | AG27: =COUNTIF(B27:AF27,"청") -> 0 | AH27: =COUNTIF(B27:AF27,"7D") -> 4 | AI27: 0 | AJ27: ='2026.4.'!AL27 -> 46174 | AK27: =IFERROR(INDEX($B$3:$AF$5,1,MATCH("청",B27:AF27,0)),"") | AL27: =AJ27 -> 46174
A28: 123 | D28: 7D | K28: 7D | N28: 청 | R28: 7D | Z28: 7D | AG28: =COUNTIF(B28:AF28,"청") -> 1 | AH28: =COUNTIF(B28:AF28,"7D") -> 4 | AI28: 0 | AJ28: ='2026.4.'!AL28 -> 46161 | AK28: =IFERROR(INDEX($B$3:$AF$5,1,MATCH("청",B28:AF28,0)),"") -> 46155 | AL28: =IFERROR(AK28+40,"") -> 46195
A29: 7D | B29: =COUNTIF(B6:B28,"7D") -> 3 | C29: =COUNTIF(C6:C28,"7D") -> 3 | D29: =COUNTIF(D6:D28,"7D") -> 3 | E29: =COUNTIF(E6:E28,"7D") -> 3 | F29: =COUNTIF(F6:F28,"7D") -> 3 | G29: =COUNTIF(G6:G28,"7D") -> 2 | H29: =COUNTIF(H6:H28,"7D") -> 3 | I29: =COUNTIF(I6:I28,"7D") -> 3 | ... AF29: =COUNTIF(AF6:AF28,"7D") -> 3 | AH29: =SUM(B29:AF29) -> 90
A30: 4M | B30: 0 | C30: 0 | D30: 0 | E30: 1 | F30: 0 | G30: 1 | H30: 1 | I30: 1 | J30: 0 | K30: 0 | L30: 1 | M30: 1 | N30: 1 | O30: 1 | P30: 1 | Q30: 0 | R30: 0 | S30: 0 | T30: 1 | U30: 1 | V30: 1 | W30: 0 | X30: 0 | Y30: 0 | Z30: 0 | AA30: 1 | AB30: 1 | AC30: 1 | AD30: 1 | AE30: 0 | AF30: 0 | AI30: =SUM(B30:AF30) -> 16
A31: 대 | B31: =COUNTIF(B6:B28,"청") -> 0 | C31: =COUNTIF(C6:C28,"청") -> 0 | D31: =COUNTIF(D6:D28,"청") -> 0 | E31: =COUNTIF(E6:E28,"청") -> 1 | F31: =COUNTIF(F6:F28,"청") -> 0 | G31: =COUNTIF(G6:G28,"청") -> 1 | H31: =COUNTIF(H6:H28,"청") -> 1 | I31: =COUNTIF(I6:I28,"청") -> 1 | ... AF31: =COUNTIF(AF6:AF28,"청") -> 0 | AH31: =SUM(B31:AF31) -> 16
B34: 근로자날 | E34: 46143 | H34: 46143
B35: 어린이날 | E35: 46147 | H35: 46147 | X35: 월상장비점검일
B36: 5∙18 | E36: 46160 | H36: 46160 | X36: 2, 6, 11월
B37: 부처님오신날 | E37: 46166 | H37: 46166
B38: 부처님대체공휴일 | E38: 46167 | H38: 46167 | X38: 대청소정비일
B39: 춘계체육행사 | E39: 46164 | H39: 46171 | X39: 3, 11월

Sheet 2026.6.
A1: 전동차 정기검사 및 대청소 계획
A2: [2026.6.] [차량운영처 차량팀]
A3: 일자 | B3: 46174 | C3: 46175 | D3: 46176 | E3: 46177 | F3: 46178 | G3: 46179 | H3: 46180 | I3: 46181 | J3: 46182 | K3: 46183 | L3: 46184 | M3: 46185 | N3: 46186 | O3: 46187 | P3: 46188 | Q3: 46189 | R3: 46190 | S3: 46191 | T3: 46192 | U3: 46193 | V3: 46194 | W3: 46195 | X3: 46196 | Y3: 46197 | Z3: 46198 | AA3: 46199 | AB3: 46200 | AC3: 46201 | AD3: 46202 | AE3: 46203 | AG3: 소계
A5: 편성 요일 | B5: 46174 | C5: 46175 | D5: 46176 | E5: 46177 | F5: 46178 | G5: 46179 | H5: 46180 | I5: 46181 | J5: 46182 | K5: 46183 | L5: 46184 | M5: 46185 | N5: 46186 | O5: 46187 | P5: 46188 | Q5: 46189 | R5: 46190 | S5: 46191 | T5: 46192 | U5: 46193 | V5: 46194 | W5: 46195 | X5: 46196 | Y5: 46197 | Z5: 46198 | AA5: 46199 | AB5: 46200 | AC5: 46201 | AD5: 46202 | AE5: 46203 | AG5: 대 | AH5: 7D | AI5: 4M | AJ5: 시행 만료일 | AK5: 이달 시행일 | AL5: 다음 시행일
A6: 101 | E6: 7D | L6: 7D | R6: 7D | Y6: 7D | AD6: 청 | AG6: =COUNTIF(B6:AF6,"청") -> 1 | AH6: =COUNTIF(B6:AF6,"7D") -> 4 | AI6: 0 | AJ6: ='2026.5.'!AL6 -> 46208 | AK6: =IFERROR(INDEX($B$3:$AF$5,1,MATCH("청",B6:AF6,0)),"") -> 46202 | AL6: =IFERROR(AK6+40,"") -> 46242
A7: 102 | B7: 7D | I7: 7D | K7: 청 | O7: 7D | V7: 7D | AC7: 7D | AG7: =COUNTIF(B7:AF7,"청") -> 1 | AH7: =COUNTIF(B7:AF7,"7D") -> 5 | AI7: 0 | AJ7: ='2026.5.'!AL7 -> 46180 | AK7: =IFERROR(INDEX($B$3:$AF$5,1,MATCH("청",B7:AF7,0)),"") -> 46183 | AL7: =IFERROR(AK7+40,"") -> 46223
A8: 103 | D8: 7D | K8: 7D | P8: 103(8M) | T8: 청 | AA8: 7D | AG8: =COUNTIF(B8:AF8,"청") -> 1 | AH8: =COUNTIF(B8:AF8,"7D") -> 3 | AI8: 0 | AJ8: ='2026.5.'!AL8 -> 46210 | AK8: =IFERROR(INDEX($B$3:$AF$5,1,MATCH("청",B8:AF8,0)),"") -> 46192 | AL8: =IFERROR(AK8+40,"") -> 46232
A9: 104 | B9: 청 | D9: 7D | K9: 7D | R9: 7D | Y9: 7D | AG9: =COUNTIF(B9:AF9,"청") -> 1 | AH9: =COUNTIF(B9:AF9,"7D") -> 4 | AI9: 0 | AJ9: ='2026.5.'!AL9 -> 46173 | AK9: =IFERROR(INDEX($B$3:$AF$5,1,MATCH("청",B9:AF9,0)),"") -> 46174 | AL9: =IFERROR(AK9+40,"") -> 46214
A10: 105 | B10: 7D | I10: 7D | P10: 7D | Q10: 청 | W10: 7D | AD10: 7D | AG10: =COUNTIF(B10:AF10,"청") -> 1 | AH10: =COUNTIF(B10:AF10,"7D") -> 5 | AI10: 0 | AJ10: ='2026.5.'!AL10 -> 46188 | AK10: =IFERROR(INDEX($B$3:$AF$5,1,MATCH("청",B10:AF10,0)),"") -> 46189 | AL10: =IFERROR(AK10+40,"") -> 46229
A11: 106 | F11: 청 | H11: 7D | O11: 7D | W11: 106(4M) | AA11: 청 | AG11: =COUNTIF(B11:AF11,"청") -> 2 | AH11: =COUNTIF(B11:AF11,"7D") -> 2 | AI11: 0 | AJ11: ='2026.5.'!AL11 -> 46176 | AK11: 46199 | AL11: =IFERROR(AK11+40,"") -> 46239
A12: 107 | H12: 7D | L12: 청 | O12: 7D | V12: 7D | AC12: 7D | AG12: =COUNTIF(B12:AF12,"청") -> 1 | AH12: =COUNTIF(B12:AF12,"7D") -> 4 | AI12: 0 | AJ12: ='2026.5.'!AL12 -> 46181 | AK12: =IFERROR(INDEX($B$3:$AF$5,1,MATCH("청",B12:AF12,0)),"") -> 46184 | AL12: =IFERROR(AK12+40,"") -> 46224
A13: 108 | B13: 7D | G13: 7D | M13: 7D | S13: 7D | Z13: 7D | AG13: =COUNTIF(B13:AF13,"청") -> 0 | AH13: =COUNTIF(B13:AF13,"7D") -> 5 | AI13: 0 | AJ13: ='2026.5.'!AL13 -> 46209 | AK13: =IFERROR(INDEX($B$3:$AF$5,1,MATCH("청",B13:AF13,0)),"") | AL13: =AJ13 -> 46209
A14: 109 | G14: 7D | I14: 청 | N14: 7D | U14: 7D | AA14: 109(1Y) | AG14: =COUNTIF(B14:AF14,"청") -> 1 | AH14: =COUNTIF(B14:AF14,"7D") -> 3 | AI14: 0 | AJ14: ='2026.5.'!AL14 -> 46179 | AK14: =IFERROR(INDEX($B$3:$AF$5,1,MATCH("청",B14:AF14,0)),"") -> 46181 | AL14: =IFERROR(AK14+40,"") -> 46221
A15: 110 | E15: 7D | L15: 7D | S15: 7D | Z15: 7D | AG15: =COUNTIF(B15:AF15,"청") -> 0 | AH15: =COUNTIF(B15:AF15,"7D") -> 4 | AI15: 0 | AJ15: ='2026.5.'!AL15 -> 46211 | AK15: =IFERROR(INDEX($B$3:$AF$5,1,MATCH("청",B15:AF15,0)),"") | AL15: =AJ15 -> 46211
A16: 111 | F16: 7D | M16: 7D | T16: 7D | Z16: 청 | AA16: 7D | AG16: =COUNTIF(B16:AF16,"청") -> 1 | AH16: =COUNTIF(B16:AF16,"7D") -> 4 | AI16: 0 | AJ16: ='2026.5.'!AL16 -> 46201 | AK16: =IFERROR(INDEX($B$3:$AF$5,1,MATCH("청",B16:AF16,0)),"") -> 46198 | AL16: =IFERROR(AK16+40,"") -> 46238
A17: 112 | E17: 7D | L17: 7D | S17: 청 | T17: 7D | AA17: 7D | AG17: =COUNTIF(B17:AF17,"청") -> 1 | AH17: =COUNTIF(B17:AF17,"7D") -> 4 | AI17: 0 | AJ17: ='2026.5.'!AL17 -> 46193 | AK17: =IFERROR(INDEX($B$3:$AF$5,1,MATCH("청",B17:AF17,0)),"") -> 46191 | AL17: =IFERROR(AK17+40,"") -> 46231
A18: 113 | F18: 7D | M18: 7D | S18: 7D | X18: 청 | Z18: 7D | AG18: =COUNTIF(B18:AF18,"청") -> 1 | AH18: =COUNTIF(B18:AF18,"7D") -> 4 | AI18: 0 | AJ18: ='2026.5.'!AL18 -> 46196 | AK18: =IFERROR(INDEX($B$3:$AF$5,1,MATCH("청",B18:AF18,0)),"") -> 46196 | AL18: =IFERROR(AK18+40,"") -> 46236
A19: 114 | C19: 청 | I19: 7D | P19: 7D | W19: 7D | AD19: 7D | AG19: =COUNTIF(B19:AF19,"청") -> 1 | AH19: =COUNTIF(B19:AF19,"7D") -> 4 | AI19: 0 | AJ19: ='2026.5.'!AL19 -> 46175 | AK19: =IFERROR(INDEX($B$3:$AF$5,1,MATCH("청",B19:AF19,0)),"") -> 46175 | AL19: =IFERROR(AK19+40,"") -> 46215
A20: 115 | H20: 7D | M20: 청 | N20: 7D | U20: 7D | AB20: 7D | AG20: =COUNTIF(B20:AF20,"청") -> 1 | AH20: =COUNTIF(B20:AF20,"7D") -> 4 | AI20: 0 | AJ20: ='2026.5.'!AL20 -> 46186 | AK20: =IFERROR(INDEX($B$3:$AF$5,1,MATCH("청",B20:AF20,0)),"") -> 46185 | AL20: =IFERROR(AK20+40,"") -> 46225
A21: 116 | D21: 7D | K21: 7D | R21: 7D | Y21: 7D | AE21: 청 | AG21: =COUNTIF(B21:AF21,"청") -> 1 | AH21: =COUNTIF(B21:AF21,"7D") -> 4 | AI21: 0 | AJ21: ='2026.5.'!AL21 -> 46203 | AK21: =IFERROR(INDEX($B$3:$AF$5,1,MATCH("청",B21:AF21,0)),"") -> 46203 | AL21: =IFERROR(AK21+40,"") -> 46243
A22: 117 | B22: 117편성(6Y, 5.26.~7.10.) | AG22: =COUNTIF(B22:AF22,"청") -> 0 | AH22: =COUNTIF(B22:AF22,"7D") -> 0 | AI22: 0 | AJ22: ='2026.5.'!AL22 -> 46189 | AK22: =IFERROR(INDEX($B$3:$AF$5,1,MATCH("청",B22:AF22,0)),"") | AL22: =AJ22 -> 46189
A23: 118 | F23: 7D | J23: 118(8M) | P23: 청 | T23: 7D | AB23: 7D | AG23: =COUNTIF(B23:AF23,"청") -> 1 | AH23: =COUNTIF(B23:AF23,"7D") -> 3 | AI23: 0 | AJ23: ='2026.5.'!AL23 -> 46197 | AK23: =IFERROR(INDEX($B$3:$AF$5,1,MATCH("청",B23:AF23,0)),"") -> 46188 | AL23: =IFERROR(AK23+40,"") -> 46228
A24: 119 | C24: 7D | J24: 7D | Q24: 7D | R24: 청 | X24: 7D | AE24: 7D | AG24: =COUNTIF(B24:AF24,"청") -> 1 | AH24: =COUNTIF(B24:AF24,"7D") -> 5 | AI24: 0 | AJ24: ='2026.5.'!AL24 -> 46190 | AK24: =IFERROR(INDEX($B$3:$AF$5,1,MATCH("청",B24:AF24,0)),"") -> 46190 | AL24: =IFERROR(AK24+40,"") -> 46230
A25: 120 | C25: 7D | J25: 7D | Q25: 7D | W25: 청 | X25: 7D | AE25: 7D | AG25: =COUNTIF(B25:AF25,"청") -> 1 | AH25: =COUNTIF(B25:AF25,"7D") -> 5 | AI25: 0 | AJ25: ='2026.5.'!AL25 -> 46194 | AK25: =IFERROR(INDEX($B$3:$AF$5,1,MATCH("청",B25:AF25,0)),"") -> 46195 | AL25: =IFERROR(AK25+40,"") -> 46235
A26: 121 | G26: 7D | N26: 7D | U26: 7D | Y26: 청 | AB26: 7D | AG26: =COUNTIF(B26:AF26,"청") -> 1 | AH26: =COUNTIF(B26:AF26,"7D") -> 4 | AI26: 0 | AJ26: ='2026.5.'!AL26 -> 46202 | AK26: =IFERROR(INDEX($B$3:$AF$5,1,MATCH("청",B26:AF26,0)),"") -> 46197 | AL26: =IFERROR(AK26+40,"") -> 46237
A27: 122 | C27: 7D | E27: 청 | J27: 7D | Q27: 7D | X27: 7D | AE27: 7D | AG27: =COUNTIF(B27:AF27,"청") -> 1 | AH27: =COUNTIF(B27:AF27,"7D") -> 5 | AI27: 0 | AJ27: ='2026.5.'!AL27 -> 46174 | AK27: =IFERROR(INDEX($B$3:$AF$5,1,MATCH("청",B27:AF27,0)),"") -> 46177 | AL27: =IFERROR(AK27+40,"") -> 46217
A28: 123 | C28: 123(1Y) | J28: 청 | P28: 7D | W28: 7D | AD28: 7D | AG28: =COUNTIF(B28:AF28,"청") -> 1 | AH28: =COUNTIF(B28:AF28,"7D") -> 3 | AI28: 0 | AJ28: ='2026.5.'!AL28 -> 46195 | AK28: =IFERROR(INDEX($B$3:$AF$5,1,MATCH("청",B28:AF28,0)),"") -> 46182 | AL28: =IFERROR(AK28+40,"") -> 46222
A29: 7D | B29: =COUNTIF(B6:B28,"7D") -> 3 | C29: =COUNTIF(C6:C28,"7D") -> 3 | D29: =COUNTIF(D6:D28,"7D") -> 3 | E29: =COUNTIF(E6:E28,"7D") -> 3 | F29: =COUNTIF(F6:F28,"7D") -> 3 | G29: =COUNTIF(G6:G28,"7D") -> 3 | H29: =COUNTIF(H6:H28,"7D") -> 3 | I29: =COUNTIF(I6:I28,"7D") -> 3 | ... AF29: =COUNTIF(AF6:AF28,"7D") -> 0 | AH29: =SUM(B29:AF29) -> 88
A30: 4M | B30: 1 | C30: 1 | D30: 0 | E30: 1 | F30: 1 | G30: 0 | H30: 0 | I30: 1 | J30: 1 | K30: 1 | L30: 1 | M30: 1 | N30: 0 | O30: 0 | P30: 1 | Q30: 1 | R30: 1 | S30: 1 | T30: 0 | U30: 0 | V30: 0 | W30: 1 | X30: 1 | Y30: 1 | Z30: 1 | AA30: 1 | AB30: 0 | AC30: 0 | AD30: 1 | AE30: 1 | AF30: 0 | AI30: =SUM(B30:AF30) -> 20
A31: 대 | B31: =COUNTIF(B6:B28,"청") -> 1 | C31: =COUNTIF(C6:C28,"청") -> 1 | D31: =COUNTIF(D6:D28,"청") -> 0 | E31: =COUNTIF(E6:E28,"청") -> 1 | F31: =COUNTIF(F6:F28,"청") -> 1 | G31: =COUNTIF(G6:G28,"청") -> 0 | H31: =COUNTIF(H6:H28,"청") -> 0 | I31: =COUNTIF(I6:I28,"청") -> 1 | ... AF31: =COUNTIF(AF6:AF28,"청") -> 0 | AH31: =SUM(B31:AF31) -> 21
T32: 6/19,월상장비점검일
B34: 지방선거 | E34: 46176 | H34: 46176
B35: 현충일 | E35: 46179 | H35: 46179 | X35: 월상장비점검일
X36: 2, 6, 11월
X38: 대청소정비일
X39: 3, 11월

Sheet 2026.7.
A1: 전동차 정기검사 및 대청소 계획
A2: [2026.7.] [차량운영처 차량팀]
A3: 일자 | B3: 46204 | C3: 46205 | D3: 46206 | E3: 46207 | F3: 46208 | G3: 46209 | H3: 46210 | I3: 46211 | J3: 46212 | K3: 46213 | L3: 46214 | M3: 46215 | N3: 46216 | O3: 46217 | P3: 46218 | Q3: 46219 | R3: 46220 | S3: 46221 | T3: 46222 | U3: 46223 | V3: 46224 | W3: 46225 | X3: 46226 | Y3: 46227 | Z3: 46228 | AA3: 46229 | AB3: 46230 | AC3: 46231 | AD3: 46232 | AE3: 46233 | AF3: 46234 | AG3: 소계
A5: 편성 요일 | B5: 46204 | C5: 46205 | D5: 46206 | E5: 46207 | F5: 46208 | G5: 46209 | H5: 46210 | I5: 46211 | J5: 46212 | K5: 46213 | L5: 46214 | M5: 46215 | N5: 46216 | O5: 46217 | P5: 46218 | Q5: 46219 | R5: 46220 | S5: 46221 | T5: 46222 | U5: 46223 | V5: 46224 | W5: 46225 | X5: 46226 | Y5: 46227 | Z5: 46228 | AA5: 46229 | AB5: 46230 | AC5: 46231 | AD5: 46232 | AE5: 46233 | AF5: 46234 | AG5: 대 | AH5: 7D | AI5: 4M | AJ5: 시행 만료일 | AK5: 이달 시행일 | AL5: 다음 시행일
A6: 101 | B6: 7D | I6: 7D | O6: 101(1Y) | V6: 청 | AA6: 7D | AG6: =COUNTIF(B6:AF6,"청") -> 1 | AH6: =COUNTIF(B6:AF6,"7D") -> 3 | AI6: 0 | AJ6: ='2026.6.'!AL6 -> 46242 | AK6: =IFERROR(INDEX($B$3:$AF$5,1,MATCH("청",B6:AF6,0)),"") -> 46224 | AL6: =IFERROR(AK6+40,"") -> 46264
A7: 102 | F7: 7D | M7: 7D | T7: 7D | U7: 청 | AA7: 7D | AG7: =COUNTIF(B7:AF7,"청") -> 1 | AH7: =COUNTIF(B7:AF7,"7D") -> 4 | AI7: 0 | AJ7: ='2026.6.'!AL7 -> 46223 | AK7: =IFERROR(INDEX($B$3:$AF$5,1,MATCH("청",B7:AF7,0)),"") -> 46223 | AL7: =IFERROR(AK7+40,"") -> 46263
A8: 103 | D8: 7D | K8: 7D | R8: 7D | W8: 청 | Y8: 7D | AF8: 7D | AG8: =COUNTIF(B8:AF8,"청") -> 1 | AH8: =COUNTIF(B8:AF8,"7D") -> 5 | AI8: 0 | AJ8: ='2026.6.'!AL8 -> 46232 | AK8: =IFERROR(INDEX($B$3:$AF$5,1,MATCH("청",B8:AF8,0)),"") -> 46225 | AL8: =IFERROR(AK8+40,"") -> 46265
A9: 104 | B9: 7D | D9: 청 | H9: 7D | O9: 7D | V9: 104(8M) | AB9: 청 | AE9: 7D | AG9: =COUNTIF(B9:AF9,"청") -> 2 | AH9: =COUNTIF(B9:AF9,"7D") -> 4 | AI9: 0 | AJ9: ='2026.6.'!AL9 -> 46214 | AK9: 45865 | AL9: =IFERROR(AK9+40,"") -> 45905
A10: 105 | G10: 7D | N10: 7D | U10: 7D | X10: 청 | AB10: 7D | AG10: =COUNTIF(B10:AF10,"청") -> 1 | AH10: =COUNTIF(B10:AF10,"7D") -> 4 | AI10: 0 | AJ10: ='2026.6.'!AL10 -> 46229 | AK10: =IFERROR(INDEX($B$3:$AF$5,1,MATCH("청",B10:AF10,0)),"") -> 46226 | AL10: =IFERROR(AK10+40,"") -> 46266
A11: 106 | D11: 7D | K11: 7D | R11: 7D | Y11: 7D | AD11: 청 | AF11: 7D | AG11: =COUNTIF(B11:AF11,"청") -> 1 | AH11: =COUNTIF(B11:AF11,"7D") -> 5 | AI11: 0 | AJ11: ='2026.6.'!AL11 -> 46239 | AK11: =IFERROR(INDEX($B$3:$AF$5,1,MATCH("청",B11:AF11,0)),"") -> 46232 | AL11: =IFERROR(AK11+40,"") -> 46272
A12: 107 | F12: 7D | K12: 청 | M12: 7D | T12: 7D | Z12: 7D | AF12: 107 | AG12: =COUNTIF(B12:AF12,"청") -> 1 | AH12: =COUNTIF(B12:AF12,"7D") -> 4 | AI12: 0 | AJ12: ='2026.6.'!AL12 -> 46224 | AK12: =IFERROR(INDEX($B$3:$AF$5,1,MATCH("청",B12:AF12,0)),"") -> 46213 | AL12: =IFERROR(AK12+40,"") -> 46253
A13: 108 | B13: 청 | C13: 7D | J13: 7D | Q13: 7D | X13: 7D | AE13: 7D | AG13: =COUNTIF(B13:AF13,"청") -> 1 | AH13: =COUNTIF(B13:AF13,"7D") -> 5 | AI13: 0 | AJ13: ='2026.6.'!AL13 -> 46209 | AK13: =IFERROR(INDEX($B$3:$AF$5,1,MATCH("청",B13:AF13,0)),"") -> 46204 | AL13: =IFERROR(AK13+40,"") -> 46244
A14: 109 | C14: 청 | I14: 7D | P14: 7D | W14: 7D | AD14: 7D | AG14: =COUNTIF(B14:AF14,"청") -> 1 | AH14: =COUNTIF(B14:AF14,"7D") -> 4 | AI14: 0 | AJ14: ='2026.6.'!AL14 -> 46221 | AK14: =IFERROR(INDEX($B$3:$AF$5,1,MATCH("청",B14:AF14,0)),"") -> 46205 | AL14: =IFERROR(AK14+40,"") -> 46245
A15: 110 | C15: 7D | G15: 청 | J15: 7D | Q15: 7D | X15: 7D | AE15: 7D | AG15: =COUNTIF(B15:AF15,"청") -> 1 | AH15: =COUNTIF(B15:AF15,"7D") -> 5 | AI15: 0 | AJ15: ='2026.6.'!AL15 -> 46211 | AK15: =IFERROR(INDEX($B$3:$AF$5,1,MATCH("청",B15:AF15,0)),"") -> 46209 | AL15: =IFERROR(AK15+40,"") -> 46249
A16: 111 | D16: 7D | K16: 7D | R16: 7D | Y16: 7D | AC16: 청 | AF16: 7D | AG16: =COUNTIF(B16:AF16,"청") -> 1 | AH16: =COUNTIF(B16:AF16,"7D") -> 5 | AI16: 0 | AJ16: ='2026.6.'!AL16 -> 46238 | AK16: =IFERROR(INDEX($B$3:$AF$5,1,MATCH("청",B16:AF16,0)),"") -> 46231 | AL16: =IFERROR(AK16+40,"") -> 46271
A17: 112 | C17: 112(8M) | I17: 청 | P17: 7D | W17: 7D | AC17: 7D | AG17: =COUNTIF(B17:AF17,"청") -> 1 | AH17: =COUNTIF(B17:AF17,"7D") -> 3 | AI17: 0 | AJ17: ='2026.6.'!AL17 -> 46231 | AK17: =IFERROR(INDEX($B$3:$AF$5,1,MATCH("청",B17:AF17,0)),"") -> 46211 | AL17: =IFERROR(AK17+40,"") -> 46251
A18: 113 | C18: 7D | J18: 7D | Q18: 7D | X18: 7D | AD18: 7D | AE18: 청 | AG18: =COUNTIF(B18:AF18,"청") -> 1 | AH18: =COUNTIF(B18:AF18,"7D") -> 5 | AI18: 0 | AJ18: ='2026.6.'!AL18 -> 46236 | AK18: =IFERROR(INDEX($B$3:$AF$5,1,MATCH("청",B18:AF18,0)),"") -> 46233 | AL18: =IFERROR(AK18+40,"") -> 46273
A19: 114 | G19: 7D | H19: 청 | N19: 7D | U19: 7D | AB19: 7D | AG19: =COUNTIF(B19:AF19,"청") -> 1 | AH19: =COUNTIF(B19:AF19,"7D") -> 4 | AI19: 0 | AJ19: ='2026.6.'!AL19 -> 46215 | AK19: =IFERROR(INDEX($B$3:$AF$5,1,MATCH("청",B19:AF19,0)),"") -> 46210 | AL19: =IFERROR(AK19+40,"") -> 46250
A20: 115 | E20: 7D | L20: 7D | P20: 청 | S20: 7D | Z20: 7D | AG20: =COUNTIF(B20:AF20,"청") -> 1 | AH20: =COUNTIF(B20:AF20,"7D") -> 4 | AI20: 0 | AJ20: ='2026.6.'!AL20 -> 46225 | AK20: =IFERROR(INDEX($B$3:$AF$5,1,MATCH("청",B20:AF20,0)),"") -> 46218 | AL20: =IFERROR(AK20+40,"") -> 46258
A21: 116 | B21: 7D | I21: 7D | P21: 7D | W21: 7D | AD21: 7D | AG21: =COUNTIF(B21:AF21,"청") -> 0 | AH21: =COUNTIF(B21:AF21,"7D") -> 5 | AI21: 0 | AJ21: ='2026.6.'!AL21 -> 46243 | AK21: =IFERROR(INDEX($B$3:$AF$5,1,MATCH("청",B21:AF21,0)),"") | AL21: =AJ21 -> 46243
A22: 117 | B22: 117편성(6Y, 5.26.~7.10.) | N22: 청 | S22: 7D | Z22: 7D | AG22: =COUNTIF(B22:AF22,"청") -> 1 | AH22: =COUNTIF(B22:AF22,"7D") -> 2 | AI22: 0 | AJ22: ='2026.6.'!AL22 -> 46189 | AK22: =IFERROR(INDEX($B$3:$AF$5,1,MATCH("청",B22:AF22,0)),"") -> 46216 | AL22: =IFERROR(AK22+40,"") -> 46256
A23: 118 | E23: 7D | L23: 7D | P23: 118편성(6Y, 7.15.~8.31.) | AG23: =COUNTIF(B23:AF23,"청") -> 0 | AH23: =COUNTIF(B23:AF23,"7D") -> 2 | AI23: 0 | AJ23: ='2026.6.'!AL23 -> 46228 | AK23: =IFERROR(INDEX($B$3:$AF$5,1,MATCH("청",B23:AF23,0)),"") | AL23: =AJ23 -> 46228
A24: 119 | G24: 7D | N24: 7D | U24: 7D | AB24: 119(8M) | AF24: 청 | AG24: =COUNTIF(B24:AF24,"청") -> 1 | AH24: =COUNTIF(B24:AF24,"7D") -> 3 | AI24: 0 | AJ24: ='2026.6.'!AL24 -> 46230 | AK24: =IFERROR(INDEX($B$3:$AF$5,1,MATCH("청",B24:AF24,0)),"") -> 46234 | AL24: =IFERROR(AK24+40,"") -> 46274
A25: 120 | H25: 7D | O25: 7D | V25: 7D | Y25: 청 | AC25: 7D | AG25: =COUNTIF(B25:AF25,"청") -> 1 | AH25: =COUNTIF(B25:AF25,"7D") -> 4 | AI25: 0 | AJ25: ='2026.6.'!AL25 -> 46235 | AK25: =IFERROR(INDEX($B$3:$AF$5,1,MATCH("청",B25:AF25,0)),"") -> 46227 | AL25: =IFERROR(AK25+40,"") -> 46267
A26: 121 | E26: 7D | I26: 121(4M) | O26: 청 | V26: 7D | AB26: 7D | AG26: =COUNTIF(B26:AF26,"청") -> 1 | AH26: =COUNTIF(B26:AF26,"7D") -> 3 | AI26: 0 | AJ26: ='2026.6.'!AL26 -> 46237 | AK26: =IFERROR(INDEX($B$3:$AF$5,1,MATCH("청",B26:AF26,0)),"") -> 46217 | AL26: =IFERROR(AK26+40,"") -> 46257
A27: 122 | H27: 7D | J27: 청 | O27: 7D | V27: 7D | AC27: 7D | AG27: =COUNTIF(B27:AF27,"청") -> 1 | AH27: =COUNTIF(B27:AF27,"7D") -> 4 | AI27: 0 | AJ27: ='2026.6.'!AL27 -> 46217 | AK27: =IFERROR(INDEX($B$3:$AF$5,1,MATCH("청",B27:AF27,0)),"") -> 46212 | AL27: =IFERROR(AK27+40,"") -> 46252
A28: 123 | F28: 7D | M28: 7D | Q28: 청 | T28: 7D | AA28: 7D | AG28: =COUNTIF(B28:AF28,"청") -> 1 | AH28: =COUNTIF(B28:AF28,"7D") -> 4 | AI28: 0 | AJ28: ='2026.6.'!AL28 -> 46222 | AK28: =IFERROR(INDEX($B$3:$AF$5,1,MATCH("청",B28:AF28,0)),"") -> 46219 | AL28: =IFERROR(AK28+40,"") -> 46259
